Workbook

Sheet 资质数据
A2: 表1 | B2: 以神兽为基础，每次打满10%战神资及攻速法防家族资，开8孔打家族五品宠物攻击宝石（653）进行合成（合速法不需要参考数据直接干就是了，其他情况下合攻收益最高） | F2: 表5 | G2: double合宠版9提1（在四合宠物上打9颗合宠提资资质宝石再提取），本数据需自行加上表2宝石资
B3: 合宠最终产物 | C3: 深渊领主 | D3: 机械兽神 | E3: 多头蛇怪 | G3: 九提一载体 | H3: 深渊领主 | I3: 机械兽神 | J3: 多头蛇怪 | K3: 恶魔武士
B4: 生命资质 | C4: 2106 | D4: 1680 | E4: 2448 | G4: a类
B5: 攻击资质 | C5: 4563 | D5: 4136 | E5: 3566 | G5: 生命资质 | H5: =$C29*9/2+C4 -> 11457 | I5: =$C29*9/2+D4 -> 11031 | J5: =$C29*9/2+E4 -> 11799 | K5: =$C29*9/2+$H18 -> 11397
B6: 速度资质 | C6: 15708 | D6: 16375 | E6: 15604 | G6: 攻击资质 | H6: =$C30*9/2+C5 -> 22960.5 | I6: =$C30*9/2+D5 -> 22533.5 | J6: =$C30*9/2+E5 -> 21963.5 | K6: =$C30*9/2+$H19 -> 23869.5
B7: 法力资质 | C7: 10527 | D7: 10694 | E7: 11291 | G7: 速度资质 | H7: =$C31*9/2+C6 -> 87238.5 | I7: =$C31*9/2+D6 -> 87905.5 | J7: =$C31*9/2+E6 -> 87134.5 | K7: =$C31*9/2+$H20 -> 86780.5
B8: 防御资质 | C8: 2686 | D8: 2686 | E8: 2686 | G8: 法力资质 | H8: =$C32*9/2+C7 -> 59295 | I8: =$C32*9/2+D7 -> 59462 | J8: =$C32*9/2+E7 -> 60059 | K8: =$C32*9/2+$H21 -> 59906
G9: 防御资质 | H9: =$C33*9/2+C8 -> 14773 | I9: =$C33*9/2+D8 -> 14773 | J9: =$C33*9/2+E8 -> 14773 | K9: =$C33*9/2+$H22 -> 14864
A10: 表2 | B10: 最终打石头（8+3）提取时多增加部分（目标为多满的情况下，提血效益最高，其次是攻防）（左列可直接加在表1和表6数据上，右列应用于表5同上操作） | G10: b类
B11: 生命 | C11: 2406 | D11: 九提一数值 | E11: =C11*9/2 -> 10827 | G11: 生命资质 | H11: =$D29*9/2+C4 -> 11799 | I11: =$D29*9/2+D4 -> 11373 | J11: =$D29*9/2+E4 -> 12141 | K11: =$D29*9/2+H18 -> 11739
B12: 攻击 | C12: 3589 | E12: =C12*9/2 -> 16150.5 | G12: 攻击资质 | H12: =$D30*9/2+C5 -> 21963.5 | I12: =$D30*9/2+D5 -> 21536.5 | J12: =$D30*9/2+E5 -> 20966.5 | K12: =$D30*9/2+H19 -> 22872.5
B13: 速度 | C13: 3042 | E13: =C13*9/2 -> 13689 | G13: 速度资质 | H13: =$D31*9/2+C6 -> 87134.5 | I13: =$D31*9/2+D6 -> 87801.5 | J13: =$D31*9/2+E6 -> 87030.5 | K13: =$D31*9/2+H20 -> 86676.5
B14: 法力 | C14: 应该没人提法吧 | E14: 不提 | G14: 法力资质 | H14: =$D32*9/2+C7 -> 60059 | I14: =$D32*9/2+D7 -> 60226 | J14: =$D32*9/2+E7 -> 60823 | K14: =$D32*9/2+H21 -> 60670
B15: 防御 | C15: 2400 | E15: =C15*9/2 -> 10800 | G15: 防御资质 | H15: =$D33*9/2+C8 -> 14773 | I15: =$D33*9/2+D8 -> 14773 | J15: =$D33*9/2+E8 -> 14773 | K15: =$D33*9/2+H22 -> 14864
A17: 表3 | B17: 合宠产物明细 | C17: 产物分布 | F17: 表6 | G17: 其他参考数据 | H17: 恶魔武士四合 | I17: 表7 | J17: 自合过程中合攻合速提出资质差别（直接加到表1和表6数据上*以上已含有攻击项*）
B18: 基础宠物 | C18: 深渊领主概率 | D18: 机械兽神概率 | E18: 多头蛇怪概率 | G18: 生命资质 | H18: 2046
B19: 杀手猫 | C19: =1/3 -> 0.33333333 | D19: =1/3 -> 0.33333333 | E19: =1/3 -> 0.33333333 | G19: 攻击资质 | H19: 5472
B20: 梦彩狼 | C20: =1/9 -> 0.11111111 | D20: =1/3 -> 0.33333333 | E20: =5/9 -> 0.55555556 | G20: 速度资质 | H20: 15250 | J20: 合攻额外提出 | K20: 427
B21: 雷火兽 | C21: =1/9 -> 0.11111111 | D21: =1/3 -> 0.33333333 | E21: =5/9 -> 0.55555556 | G21: 法力资质 | H21: 11138 | J21: 合速额外提出 | K21: 2854
B22: 熊猫酒仙（粽子） | C22: =1/3 -> 0.33333333 | D22: =1/3 -> 0.33333333 | E22: =1/3 -> 0.33333333 | G22: 防御资质 | H22: 2777
B23: 剩蛋猴 | C23: 0 | D23: 0 | E23: 0
B24: 长江8号 | C24: 0 | D24: 0 | E24: 0 | F24: 表8 | G24: double合宠纯a类（基础宠及九提一载体全用杀手猫和鹿萌萌）做资法（注：目前我算出五满资性价比最高做法） | K24: 准备材料：神兽召唤卷轴*10（召唤鹿萌萌）；提资器*10，合成石*40；启魂50套（普启*100，超启*50，圣启*50），完美启魂*1；普通披风*10，五品宠物生命宝石（魔族）*58，五品宠物防御宝石（魔族）*44；战神高级积分1000万点（换宠物基础资质成长卡*500），家族贡献88万（换攻、速、法、防宝石强化卡各40套）。 花费为：提资套（45*10=450），完美启魂（3.5*1=3.5），普通披风（最少3.5*10=35），五品魔族宝石（102*0.2=20.4），共计450+3.5+35+20.4=508.9 做法：召唤鹿萌萌，每次合成开8孔打满家族五品攻击宝石，打10%战神资及20%攻速法防家族资四合，10只完成四次合成后留下一只四合出来的深渊领主（如果没有就留多头蛇怪）开9孔，剩下9只全部开8孔打10%战神资装备普通披风，5只打满魔族生命石，4只打满魔族防御石（不需要区分，随意打，总共55生命44防御随便打都一样），将9只全部用提资器提掉，将这9颗资质宝石打在留下的深渊领主（或多头蛇怪）上，打10%战神资装备普通披风（3颗魔族生命宝石），然后提掉就得到左侧数据的一颗宠物宝石
B25: 鹿萌萌 | C25: =1/3 -> 0.33333333 | D25: =1/3 -> 0.33333333 | E25: =1/3 -> 0.33333333
G26: 生命资质 | H26: =C29*5.5 -> 11429 | I26: 以五血四防比例提资，九提一时再加三生命石普通披风 | J26: =C11*5/2+H26+C11/11*3 -> 18100.182
A27: 表4 | B27: 合成提资期望值 | C27: a类 | D27: b类 | G27: 攻击资质 | H27: =C30*5.5 -> 22485.833 | J27: =H27 -> 22485.833
B28: 期望资质 | C28: 杀手猫/熊猫酒仙（粽子）/鹿萌萌 | D28: 梦彩狼/雷火兽 | G28: 速度资质 | H28: =C31*5.5 -> 87426.167 | J28: =H28 -> 87426.167
B29: 生命 | C29: =C$19*C4+D$19*D4+D$19*E4 -> 2078 | D29: =C$20*C4+D$20*D4+E$20*E4 -> 2154 | G29: 法力资质 | H29: =C32*5.5 -> 59605.333 | J29: =H29 -> 59605.333
B30: 攻击 | C30: =C$19*C5+D$19*D5+D$19*E5 -> 4088.3333 | D30: =C$20*C5+D$20*D5+E$20*E5 -> 3866.7778 | G30: 防御资质 | H30: =C33*5.5 -> 14773 | J30: =H30+C15*4/2 -> 19573
B31: 速度 | C31: =C$19*C6+D$19*D6+D$19*E6 -> 15895.667 | D31: =C$20*C6+D$20*D6+E$20*E6 -> 15872.556 | G31: 注意：本做法相比于三合熊猫做法，用稍少的血防换取稍高的攻击及大量的速法（接近一颗速法资），仅在于主攻血防且追求更高速法属性的情况下（五满）性价比更高，缺点是需要更多家族贡献和战神高级积分（鹿萌萌可交易，使用第二个号打第一步的家族资和战神资可为主号节省200万战神高级积分和22万家族贡献）
B32: 法力 | C32: =C$19*C7+D$19*D7+D$19*E7 -> 10837.333 | D32: =C$20*C7+D$20*D7+E$20*E7 -> 11007.111
B33: 防御 | C33: =C$19*C8+D$19*D8+D$19*E8 -> 2686 | D33: =C$20*C8+D$20*D8+E$20*E8 -> 2686
A36: 表9 | B36: 宠物资质需求参考（资质转换率为游戏数据倒推，仅供参考） | D36: 已知属性增幅（贴纸共计五张，法宝共计一项，*存在复合增幅贴纸，自行查找*） | J36: 宠物资质数据参考（资质转换率为游戏数据倒推，仅供参考） | L36: 宠物里世界潜力： 在10000点潜力的情况下，为宠物总资质（基础资质加红色资质，不包含资质卡加成和宝石卡加成）的0.18倍转化为防御力（可以受法宝10%、天赋30%以及贴纸加成），宠物潜力最高可达到15000，此时系数为0.27。 例：某宠物拥有0基础资和84000红色防御资，在五防贴（加成112%）和天赋（加成30%）及法宝（加成10%）下，刷10000潜力可额外获得防御力38102点，百级二转分配属性点（99+408）获得防御力为463642点，总共501744点。
B37: 项目 | C37: 转化率（一点属性对应相应资质） | D37: 项目 增幅类型 | E37: 生命 | F37: 攻击 | G37: 速度 | H37: 法力 | I37: 防御 | J37: 项目 | K37: 转化率（一点资质对应相应属性）
B38: 生命 | C38: 27.77 | D38: 贴纸a | E38: 0.26 | F38: 0.26 | G38: 0.26 | H38: 0.26 | I38: 0.36 | J38: 生命 | K38: =1/27.77 -> 0.036010083
B39: 攻击 | C39: 277.77 | D39: 贴纸b | E39: 0.16 | F39: 0.2 | G39: 0.2 | H39: 0.2 | I39: 0.26 | J39: 攻击 | K39: =1/277.77 -> 0.0036001008
B40: 速度 | C40: 2081.51 | D40: 贴纸c | E40: 0.16 | F40: 0.16 | G40: 0.16 | H40: 0.16 | I40: 0.22 | J40: 速度 | K40: =1/2081.51 -> 0.00048042046
B41: 法力 | C41: 1388.73 | D41: 贴纸d | E41: 0.16 | F41: 0.16 | G41: 0.16 | H41: 0.16 | I41: 0.16 | J41: 法力 | K41: =1/1388.73 -> 0.00072008238
B42: 防御 | C42: 277.77 | D42: 贴纸e | E42: 0.12 | F42: 0.16 | G42: 0.16 | H42: 0.16 | I42: 0.12 | J42: 防御 | K42: =1/277.77 -> 0.0036001008
D43: 技能（圣） | E43: 0.8 | F43: 0.6 | G43: 0.4 | H43: 0.6 | I43: 0 | J43: 闯天关： 根据文件＂宠物攻略＂推导，生命100000防御10000以上（皆受法宝、天赋、贴纸和技能加成）
D44: 天赋 | E44: 0.1 | F44: 0.1 | G44: 0 | H44: 0.1 | I44: 0.3
...

Sheet 宠物合成表
B2: 杀手猫 | C2: 吸血猫 | D2: 野猪王 | E2: 灰大狼
B3: 熊猫酒仙（粽子） | C3: 吸血猫 | D3: 野猪王 | E3: 灰大狼
B4: 鹿萌萌 | C4: 吸血猫 | D4: 野猪王 | E4: 灰大狼
B5: 杀手猫 | C5: 吸血猫 | D5: 野猪王 | E5: 灰大狼
B6: 雷火兽 | C6: 铁金刚 | D6: 野猪王
B7: 梦彩狼 | C7: 铁金刚 | D7: 野猪王
B8: 剩蛋猴 | C8: 狐铃铛
B9: 长江8号 | C9: 狐铃铛
B10: 吸血猫 | C10: 百变魔女 | D10: 莫莉卡 | E10: 斯拉姆
B11: 灰大狼 | C11: 百变魔女 | D11: 莫莉卡 | E11: 巴欧力
B12: 野猪王 | C12: 人鱼公主 | D12: 雪人宝宝 | E12: 树之骑士
B13: 铁金刚 | C13: 人鱼公主 | D13: 雪人宝宝 | E13: 树之骑士
B14: 狐铃铛 | C14: 神灯巨人 | D14: 英克巴特
B15: 百变魔女 | C15: 黑骑士 | D15: 地狱魔 | E15: 血色狼人
B16: 树之骑士 | C16: 黑骑士 | D16: 地狱魔 | E16: 血色狼人
B17: 莫莉卡 | C17: 黑骑士 | D17: 地狱魔 | E17: 八四光年
B18: 巴欧力 | C18: 黑骑士 | D18: 地狱魔 | E18: 八四光年
B19: 雪人宝宝 | C19: 巨象王 | D19: 熊猫武圣 | E19: 冰龙宝宝
B20: 人鱼公主 | C20: 巨象王 | D20: 熊猫武圣 | E20: 冰龙宝宝
B21: 神灯巨人 | C21: 圣灵羽 | D21: 花香宝宝
B22: 英克巴特 | C22: 圣灵羽 | D22: 花香宝宝
B23: 黑骑士 | C23: 机械兽神 | D23: 深渊领主
B24: 地狱魔 | C24: 机械兽神 | D24: 深渊领主
B25: 八四光年 | D25: 深渊领主
B26: 血色狼人 | E26: 多头蛇怪
B27: 巨象王 | E27: 多头蛇怪
B28: 熊猫武圣 | E28: 多头蛇怪
B29: 冰龙宝宝 | C29: 机械兽神
B30: 圣灵羽 | F30: 暗影死神
B31: 花香宝宝 | F31: 暗影死神

Sheet 贴纸效果
A2: 品级 | B2: 名称 | C2: 攻击 | D2: 速度 | E2: 法力 | F2: 生命 | G2: 防御 | H2: 命中 | I2: 闪避 | J2: 物抗 | K2: 技抗 | L2: 爆抗 | M2: 逆物 | N2: 逆技 | O2: 致命 | P2: 爆伤
A3: 魂 | B3: 魂品NPC关重七（刘山泉）速度26% | D3: 26
A4: 神 | B4: 神品宠物人鱼公主速度20% | D4: 20
A5: 神 | B5: 神品宠物小白狼速度16%逆物8 | D5: 16 | M5: 8
A6: 神 | B6: 神品彩云地精速度16%闪避6 | D6: 16 | I6: 6
A7: 五 | B7: 五品NPC梨落速度16% | D7: 16
A8: 四 | B8: 四品宠物火蝙蝠速度12% | D8: 12
A9: 五 | B9: 五品NPC粽子精灵速度12%闪避4 | D9: 12 | I9: 4
A10: 四 | B10: 四品宠物死神鸟速度10%法力4% | D10: 10 | E10: 4
A11: 四 | B11: 四品生肖王兔防御4%速度10% | D11: 10 | G11: 4
A12: 三 | B12: 三品迷失国度邪恶灵魂速度10% | D12: 10
A13: 三 | B13: 三品迷失国度甲壳兽速度8%法力2% | D13: 8 | E13: 2
A14: 三 | B14: 三品宠物青螳速度8%技抗2 | D14: 8 | K14: 2
A15: 神 | B15: 神品NPC星澈速度6%法力16% | D15: 6 | E15: 16
A16: 二 | B16: 二品迷失国度牛蛙王子速度6%法力2% | D16: 6 | E16: 2
A17: 二 | B17: 二品宠物兔叉叉速度6% | D17: 6
A18: 四 | B18: 四品生肖王羊速度4%法力10% | D18: 4 | E18: 10
A19: 四 | B19: 四品生肖王狗防御12%速度4% | D19: 4 | G19: 12
A20: 四 | B20: 四品生肖王猴速度4%命中12 | D20: 4 | H20: 12
A21: 一 | B21: 一品宠物赤尾狐速度4% | D21: 4
A22: 三 | B22: 三品宠物帽子兔速度2%法力8% | D22: 2 | E22: 8
A23: 二 | B23: 二品宠物彩羽鸟法力6%速度2% | D23: 2 | E23: 6
A24: 三 | B24: 三品宠物天马防御10%速度2% | D24: 2 | G24: 10
A25: 二 | B25: 二品迷失国度老草泥马防御6%速度2% | D25: 2 | G25: 6
A26: 一 | B26: 一品生肖子鼠速度2% | D26: 2
A27: 魂 | B27: 魂品神泣时代逆流暴伤倍率42%致命10 | O27: 10 | P27: 42
A28: 神 | B28: 神品彩云魔魂致命10 | O28: 10
A29: 神 | B29: 神品彩云神兽命中8致命8 | H29: 8 | O29: 8
A30: 四 | B30: 四品宠物蓝虎致命6 | O30: 6
A31: 三 | B31: 三品迷失国度史前巨兽攻击力2%致命4 | C31: 2 | O31: 4
A32: 三 | B32: 三品迷失国度峭壁号令者攻击力2%致命4 | C32: 2 | O32: 4
A33: 三 | B33: 三品宠物鱼雷致命4 | O33: 4
A34: 三 | B34: 三品宠物飘飘精灵技抗2致命4 | K34: 2 | O34: 4
A35: 四 | B35: 四品生肖王马攻击力4%致命4 | C35: 4 | O35: 4
A36: 二 | B36: 二品迷失国度乱石仆从命中2致命2 | H36: 2 | O36: 2
A37: 二 | B37: 二品宠物灵毛鼠致命2 | O37: 2
A38: 四 | B38: 四品生肖王虎攻击力10%致命2 | C38: 10 | O38: 2
A39: 四 | B39: 四品宠物小恶魔命中12致命2 | H39: 12 | O39: 2
A40: 一 | B40: 一品宠物香蕉致命2 | O40: 2
A41: 魂 | B41: 魂品NPC桃子法力26% | E41: 26
...

Sheet 满属性资质需求计算器
B1: 宠物等级 | E1: 83 | F1: 进化等级 | G1: 100 | H1: 转生等级 | I1: 2
B2: 宠物基础资质 | C2: 是否有圣技 | D2: 是否有法宝 | E2: 贴纸数 | F2: 属性项 | G2: 基础属性点 | H2: 分配属性点 | I2: 贴纸 | J2: 技能（圣技） | K2: 天赋 | L2: 法宝 | M2: 所需红色资质 | N2: 属性 | S2: 生命 | T2: 攻击 | U2: 速度 | V2: 法力 | W2: 防御
A3: 单满 | C3: 是 | D3: 是 | E3: 5 | F3: 生命 | G3: =$E$1-1+$G$1*3/4 -> 157 | H3: =$G$1+IF($I$1>=1,IF($I$1=2,(INT($E$1/5)*2+70)+198,(INT($E$1/5)*2+10)+198),($E$1-1)*2) -> 400 | I3: =SUMPRODUCT(($R$3:$R$7<=E3)*$S$3:$W$7*(F3=$S$2:$W$2)) -> 0.86 | J3: =IF(C3="是",VLOOKUP(F3,$T$12:$U$16,2),0) -> 0.8 | K3: 0.1 | L3: =IF(D3="是",0.1,0) -> 0.1 | M3: =IF(F3="防御",(N3/(1+L3+K3+J3+I3)/(((H3+G3)*1.2/资质数据!$C$42)+0.18)),(N3/(1+I3+J3+K3+L3)/(H3+G3)*VLOOKUP(F:F,资质数据!$B$37:$C$42,2)-B3*1.1)/1.2) -> 726528.86 | N3: 5000000 | R3: 1 | S3: 0.26 | T3: 0.26 | U3: 0.26 | V3: 0.26 | W3: 0.36
C4: 是 | D4: 是 | E4: 4 | F4: 攻击 | G4: =$E$1-1+$G$1*3/4 -> 157 | H4: =$G$1+IF($I$1>=1,IF($I$1=2,(INT($E$1/5)*2+70)+198,(INT($E$1/5)*2+10)+198),($E$1-1)*2) -> 400 | I4: =SUMPRODUCT(($R$3:$R$7<=E4)*$S$3:$W$7*(F4=$S$2:$W$2)) -> 0.78 | J4: =IF(C4="是",VLOOKUP(F4,$T$12:$U$16,2),0) -> #N/A | K4: 0.1 | L4: =IF(D4="是",0.1,0) -> 0.1 | M4: =IF(F4="防御",(N4/(1+L4+K4+J4+I4)/(((H4+G4)*1.2/资质数据!$C$42)+0.18)),(N4/(1+I4+J4+K4+L4)/(H4+G4)*VLOOKUP(F:F,资质数据!$B$37:$C$42,2)-B4*1.1)/1.2) -> #N/A | N4: 500000 | R4: 2 | S4: 0.16 | T4: 0.2 | U4: 0.2 | V4: 0.2 | W4: 0.26
C5: 是 | D5: 是 | E5: 2 | F5: 速度 | G5: =$E$1-1+$G$1*3/4 -> 157 | H5: =$G$1+IF($I$1>=1,IF($I$1=2,(INT($E$1/5)*2+70)+198,(INT($E$1/5)*2+10)+198),($E$1-1)*2) -> 400 | I5: =SUMPRODUCT(($R$3:$R$7<=E5)*$S$3:$W$7*(F5=$S$2:$W$2)) -> 0.46 | J5: =IF(C5="是",VLOOKUP(F5,$T$12:$U$16,2),0) -> 0.4 | K5: 0 | L5: =IF(D5="是",0.1,0) -> 0.1 | M5: =IF(F5="防御",(N5/(1+L5+K5+J5+I5)/(((H5+G5)*1.2/资质数据!$C$42)+0.18)),(N5/(1+I5+J5+K5+L5)/(H5+G5)*VLOOKUP(F:F,资质数据!$B$37:$C$42,2)-B5*1.1)/1.2) -> 21202.781 | N5: 100000 | R5: 3 | S5: 0.16 | T5: 0.16 | U5: 0.16 | V5: 0.16 | W5: 0.22
C6: 是 | D6: 否 | E6: 1 | F6: 法力 | G6: =$E$1-1+$G$1*3/4 -> 157 | H6: =$G$1+IF($I$1>=1,IF($I$1=2,(INT($E$1/5)*2+70)+198,(INT($E$1/5)*2+10)+198),($E$1-1)*2) -> 400 | I6: =SUMPRODUCT(($R$3:$R$7<=E6)*$S$3:$W$7*(F6=$S$2:$W$2)) -> 0.26 | J6: =IF(C6="是",VLOOKUP(F6,$T$12:$U$16,2),0) -> #N/A | K6: 0.1 | L6: =IF(D6="是",0.1,0) -> 0 | M6: =IF(F6="防御",(N6/(1+L6+K6+J6+I6)/(((H6+G6)*1.2/资质数据!$C$42)+0.18)),(N6/(1+I6+J6+K6+L6)/(H6+G6)*VLOOKUP(F:F,资质数据!$B$37:$C$42,2)-B6*1.1)/1.2) -> #N/A | N6: 100000 | R6: 4 | S6: 0.16 | T6: 0.16 | U6: 0.16 | V6: 0.16 | W6: 0.16
C7: 是 | D7: 是 | E7: 4 | F7: 防御 | G7: =$E$1-1 -> 82 | H7: =$G$1+IF($I$1>=1,IF($I$1=2,(INT($E$1/5)*2+70)+198,(INT($E$1/5)*2+10)+198),($E$1-1)*2) -> 400 | I7: =SUMPRODUCT(($R$3:$R$7<=E7)*$S$3:$W$7*(F7=$S$2:$W$2)) -> 1 | J7: =IF(C7="是",VLOOKUP(F7,$T$12:$U$16,2),0) -> #N/A | K7: 0.3 | L7: =IF(D7="是",0.1,0) -> 0.1 | M7: =IF(F7="防御",(N7/(1+L7+K7+J7+I7)/(((H7+G7)*1.2/资质数据!$C$42)+0.18)),(N7/(1+I7+J7+K7+L7)/(H7+G7)*VLOOKUP(F:F,资质数据!$B$37:$C$42,2)-B7*1.1)/1.2) -> #N/A | N7: 500000 | R7: 5 | S7: 0.12 | T7: 0.16 | U7: 0.16 | V7: 0.16 | W7: 0.12
B8: 宠物基础资质 | C8: 是否有圣技 | D8: 是否有法宝 | E8: 贴纸数 | F8: 属性项 | G8: 基础属性点 | H8: 分配属性点 | I8: 贴纸 | J8: 技能（圣技） | K8: 天赋 | L8: 法宝 | M8: 所需红色资质 | N8: 属性 | R8: 技能（圣） | S8: 0.8 | T8: 0.6 | U8: 0.4 | V8: 0.6 | W8: 0
A9: 双满 | C9: 是 | D9: 是 | E9: 2 | F9: 攻击 | G9: =IF(F9="防御",($E$1-1),$E$1-1+$G$1*3/4) -> 157 | H9: =INT(($G$1+IF($I$1>=1,IF($I$1=2,(INT($E$1/5)*2+70)+198,(INT($E$1/5)*2+10)+198),($E$1-1)*2))/SUMPRODUCT((S20:S24=F9)*T20:X24*($T$19:$X$19=F10))) -> 193 | I9: =SUMPRODUCT(($R$3:$R$7<=E9)*$S$3:$W$7*(F9=$S$2:$W$2)) -> 0.46 | J9: =IF(C9="是",VLOOKUP(F9,$T$12:$U$16,2),0) -> #N/A | K9: =VLOOKUP(F9,$F$3:$K$7,6) -> #N/A | L9: =IF(D9="是",0.1,0) -> 0.1 | M9: =IF(F9="防御",(N9/(1+L9+K9+J9+I9)/(((H9+G9)*1.2/资质数据!$C$42)+0.18)),(N9/(1+I9+J9+K9+L9)/(H9+G9)*VLOOKUP(F:F,资质数据!$B$37:$C$42,2)-B9*1.1)/1.2) -> #N/A | N9: =VLOOKUP(F9,$F$3:$N$7,9) -> #N/A | R9: 天赋 | S9: 0.1 | T9: 0.1 | U9: 0 | V9: 0.1 | W9: 0.3
C10: 是 | D10: 否 | E10: 3 | F10: 生命 | G10: =IF(F10="防御",($E$1-1),$E$1-1+$G$1*3/4) -> 157 | H10: =$G$1+IF($I$1>=1,IF($I$1=2,(INT($E$1/5)*2+70)+198,(INT($E$1/5)*2+10)+198),($E$1-1)*2)-H9 -> 207 | I10: =SUMPRODUCT(($R$3:$R$7<=E10)*$S$3:$W$7*(F10=$S$2:$W$2)) -> 0.58 | J10: =IF(C10="是",VLOOKUP(F10,$T$12:$U$16,2),0) -> 0.8 | K10: =VLOOKUP(F10,$F$3:$K$7,6) -> 0.1 | L10: =IF(D10="是",0.1,0) -> 0 | M10: =IF(F10="防御",(N10/(1+L10+K10+J10+I10)/(((H10+G10)*1.2/资质数据!$C$42)+0.18)),(N10/(1+I10+J10+K10+L10)/(H10+G10)*VLOOKUP(F:F,资质数据!$B$37:$C$42,2)-B10*1.1)/1.2) -> 1282097.4 | N10: =VLOOKUP(F10,$F$3:$N$7,9) -> 5000000 | R10: 法宝 | S10: 0.1 | T10: 0.1 | U10: 0.1 | V10: 0.1 | W10: 0.1
B11: 宠物基础资质 | C11: 是否有圣技 | D11: 是否有法宝 | E11: 贴纸数 | F11: 属性项 | G11: 基础属性点 | H11: 分配属性点 | I11: 贴纸 | J11: 技能（圣技） | K11: 天赋 | L11: 法宝 | M11: 所需红色资质 | N11: 属性
A12: 三满 | C12: 是 | D12: 否 | E12: 1 | F12: 攻击 | G12: =IF(F12="防御",($E$1-1),$E$1-1+$G$1*3/4) -> 157 | H12: =INT(($G$1+IF($I$1>=1,IF($I$1=2,(INT($E$1/5)*2+70)+198,(INT($E$1/5)*2+10)+198),($E$1-1)*2))/(VLOOKUP($F$12,$S$28:$T$32,2)+VLOOKUP($F$13,$S$28:$T$32,2)+VLOOKUP($F$14,$S$28:$T$32,2))*VLOOKUP($F$12,$S$28:$T$32,2)) -> #N/A | I12: =SUMPRODUCT(($R$3:$R$7<=E12)*$S$3:$W$7*(F12=$S$2:$W$2)) -> 0.26 | J12: =IF(C12="是",VLOOKUP(F12,$T$12:$U$16,2),0) -> #N/A | K12: =VLOOKUP(F12,$F$3:$K$7,6) -> #N/A | L12: =IF(D12="是",0.1,0) -> 0 | M12: =IF(F12="防御",(N12/(1+L12+K12+J12+I12)/(((H12+G12)*1.2/资质数据!$C$42)+0.18)),(N12/(1+I12+J12+K12+L12)/(H12+G12)*VLOOKUP(F:F,资质数据!$B$37:$C$42,2)-B12*1.1)/1.2) -> #N/A | N12: =VLOOKUP(F12,$F$3:$N$7,9) -> #N/A | T12: 生命 | U12: 0.8
C13: 是 | D13: 否 | E13: 2 | F13: 速度 | G13: =IF(F13="防御",($E$1-1),$E$1-1+$G$1*3/4) -> 157 | H13: =INT(($G$1+IF($I$1>=1,IF($I$1=2,(INT($E$1/5)*2+70)+198,(INT($E$1/5)*2+10)+198),($E$1-1)*2))/(VLOOKUP($F$12,$S$28:$T$32,2)+VLOOKUP($F$13,$S$28:$T$32,2)+VLOOKUP($F$14,$S$28:$T$32,2))*VLOOKUP(F13,$S$28:$T$32,2)) -> #N/A | I13: =SUMPRODUCT(($R$3:$R$7<=E13)*$S$3:$W$7*(F13=$S$2:$W$2)) -> 0.46 | J13: =IF(C13="是",VLOOKUP(F13,$T$12:$U$16,2),0) -> 0.4 | K13: =VLOOKUP(F13,$F$3:$K$7,6) -> 0 | L13: =IF(D13="是",0.1,0) -> 0 | M13: =IF(F13="防御",(N13/(1+L13+K13+J13+I13)/(((H13+G13)*1.2/资质数据!$C$42)+0.18)),(N13/(1+I13+J13+K13+L13)/(H13+G13)*VLOOKUP(F:F,资质数据!$B$37:$C$42,2)-B13*1.1)/1.2) -> #N/A | N13: =VLOOKUP(F13,$F$3:$N$7,9) -> 100000 | T13: 攻击 | U13: 0.6
C14: 是 | D14: 是 | E14: 2 | F14: 法力 | G14: =IF(F14="防御",($E$1-1),$E$1-1+$G$1*3/4) -> 157 | H14: =$G$1+IF($I$1>=1,IF($I$1=2,(INT($E$1/5)*2+70)+198,(INT($E$1/5)*2+10)+198),($E$1-1)*2)-H12-H13 -> #N/A | I14: =SUMPRODUCT(($R$3:$R$7<=E14)*$S$3:$W$7*(F14=$S$2:$W$2)) -> 0.46 | J14: =IF(C14="是",VLOOKUP(F14,$T$12:$U$16,2),0) -> #N/A | K14: =VLOOKUP(F14,$F$3:$K$7,6) -> #N/A | L14: =IF(D14="是",0.1,0) -> 0.1 | M14: =IF(F14="防御",(N14/(1+L14+K14+J14+I14)/(((H14+G14)*1.2/资质数据!$C$42)+0.18)),(N14/(1+I14+J14+K14+L14)/(H14+G14)*VLOOKUP(F:F,资质数据!$B$37:$C$42,2)-B14*1.1)/1.2) -> #N/A | N14: =VLOOKUP(F14,$F$3:$N$7,9) -> #N/A | T14: 速度 | U14: 0.4
B15: 宠物基础资质 | C15: 是否有圣技 | D15: 是否有法宝 | E15: 贴纸数 | F15: 属性项 | G15: 基础属性点 | H15: 分配属性点 | I15: 贴纸 | J15: 技能（圣技） | K15: 天赋 | L15: 法宝 | M15: 所需红色资质 | N15: 属性 | T15: 法力 | U15: 0.6
A16: 四满 | C16: 是 | D16: 否 | E16: 2 | F16: 生命 | G16: =IF(F16="防御",($E$1-1),$E$1-1+$G$1*3/4) -> 157 | H16: =INT(($G$1+IF($I$1>=1,IF($I$1=2,(INT($E$1/5)*2+70)+198,(INT($E$1/5)*2+10)+198),($E$1-1)*2))/(VLOOKUP($F$16,$S$28:$T$32,2)+VLOOKUP($F$17,$S$28:$T$32,2)+VLOOKUP($F$18,$S$28:$T$32,2)+VLOOKUP($F$19,$S$28:$T$32,2))*VLOOKUP(F16,$S$28:$T$32,2)) -> #N/A | I16: =SUMPRODUCT(($R$3:$R$7<=E16)*$S$3:$W$7*(F16=$S$2:$W$2)) -> 0.42 | J16: =IF(C16="是",VLOOKUP(F16,$T$12:$U$16,2),0) -> 0.8 | K16: =VLOOKUP(F16,$F$3:$K$7,6) -> 0.1 | L16: =IF(D16="是",0.1,0) -> 0 | M16: =IF(F16="防御",(N16/(1+L16+K16+J16+I16)/(((H16+G16)*1.2/资质数据!$C$42)+0.18)),(N16/(1+I16+J16+K16+L16)/(H16+G16)*VLOOKUP(F:F,资质数据!$B$37:$C$42,2)-B16*1.1)/1.2) -> #N/A | N16: =VLOOKUP(F16,$F$3:$N$7,9) -> 5000000 | T16: 防御 | U16: 0
C17: 否 | D17: 否 | E17: 0 | F17: 法力 | G17: =IF(F17="防御",($E$1-1),$E$1-1+$G$1*3/4) -> 157 | H17: =INT(($G$1+IF($I$1>=1,IF($I$1=2,(INT($E$1/5)*2+70)+198,(INT($E$1/5)*2+10)+198),($E$1-1)*2))/(VLOOKUP($F$16,$S$28:$T$32,2)+VLOOKUP($F$17,$S$28:$T$32,2)+VLOOKUP($F$18,$S$28:$T$32,2)+VLOOKUP($F$19,$S$28:$T$32,2))*VLOOKUP(F17,$S$28:$T$32,2)) -> #N/A | I17: =SUMPRODUCT(($R$3:$R$7<=E17)*$S$3:$W$7*(F17=$S$2:$W$2)) -> 0 | J17: =IF(C17="是",VLOOKUP(F17,$T$12:$U$16,2),0) -> 0 | K17: =VLOOKUP(F17,$F$3:$K$7,6) -> #N/A | L17: =IF(D17="是",0.1,0) -> 0 | M17: =IF(F17="防御",(N17/(1+L17+K17+J17+I17)/(((H17+G17)*1.2/资质数据!$C$42)+0.18)),(N17/(1+I17+J17+K17+L17)/(H17+G17)*VLOOKUP(F:F,资质数据!$B$37:$C$42,2)-B17*1.1)/1.2) -> #N/A | N17: =VLOOKUP(F17,$F$3:$N$7,9) -> #N/A
C18: 是 | D18: 否 | E18: 1 | F18: 攻击 | G18: =IF(F18="防御",($E$1-1),$E$1-1+$G$1*3/4) -> 157 | H18: =INT(($G$1+IF($I$1>=1,IF($I$1=2,(INT($E$1/5)*2+70)+198,(INT($E$1/5)*2+10)+198),($E$1-1)*2))/(VLOOKUP($F$16,$S$28:$T$32,2)+VLOOKUP($F$17,$S$28:$T$32,2)+VLOOKUP($F$18,$S$28:$T$32,2)+VLOOKUP($F$19,$S$28:$T$32,2))*VLOOKUP(F18,$S$28:$T$32,2)) -> #N/A | I18: =SUMPRODUCT(($R$3:$R$7<=E18)*$S$3:$W$7*(F18=$S$2:$W$2)) -> 0.26 | J18: =IF(C18="是",VLOOKUP(F18,$T$12:$U$16,2),0) -> #N/A | K18: =VLOOKUP(F18,$F$3:$K$7,6) -> #N/A | L18: =IF(D18="是",0.1,0) -> 0 | M18: =IF(F18="防御",(N18/(1+L18+K18+J18+I18)/(((H18+G18)*1.2/资质数据!$C$42)+0.18)),(N18/(1+I18+J18+K18+L18)/(H18+G18)*VLOOKUP(F:F,资质数据!$B$37:$C$42,2)-B18*1.1)/1.2) -> #N/A | N18: =VLOOKUP(F18,$F$3:$N$7,9) -> #N/A
C19: 是 | D19: 是 | E19: 2 | F19: 防御 | G19: =IF(F19="防御",($E$1-1),$E$1-1+$G$1*3/4) -> 82 | H19: =INT(($G$1+IF($I$1>=1,IF($I$1=2,(INT($E$1/5)*2+70)+198,(INT($E$1/5)*2+10)+198),($E$1-1)*2))/(VLOOKUP($F$16,$S$28:$T$32,2)+VLOOKUP($F$17,$S$28:$T$32,2)+VLOOKUP($F$18,$S$28:$T$32,2)+VLOOKUP($F$19,$S$28:$T$32,2))*VLOOKUP(F19,$S$28:$T$32,2)) -> #N/A | I19: =SUMPRODUCT(($R$3:$R$7<=E19)*$S$3:$W$7*(F19=$S$2:$W$2)) -> 0.62 | J19: =IF(C19="是",VLOOKUP(F19,$T$12:$U$16,2),0) -> #N/A | K19: =VLOOKUP(F19,$F$3:$K$7,6) -> #N/A | L19: =IF(D19="是",0.1,0) -> 0.1 | M19: =IF(F19="防御",(N19/(1+L19+K19+J19+I19)/(((H19+G19)*1.2/资质数据!$C$42)+0.18)),(N19/(1+I19+J19+K19+L19)/(H19+G19)*VLOOKUP(F:F,资质数据!$B$37:$C$42,2)-B19*1.1)/1.2) -> #N/A | N19: =VLOOKUP(F19,$F$3:$N$7,9) -> #N/A | T19: 生命 | U19: 攻击 | V19: 速度 | W19: 法力 | X19: 防御
B20: 宠物基础资质 | C20: 是否有圣技 | D20: 是否有法宝 | E20: 贴纸数 | F20: 属性项 | G20: 基础属性点 | H20: 分配属性点 | I20: 贴纸 | J20: 技能（圣技） | K20: 天赋 | L20: 法宝 | M20: 所需红色资质 | N20: 属性 | S20: 生命 | T20: 2 | U20: 1.93 | V20: 1.43 | W20: 1.48 | X20: 3
A21: 五满 | B21: 1000 | C21: 是 | D21: 否 | E21: 0 | F21: 生命 | G21: =IF(F21="防御",($E$1-1),$E$1-1+$G$1*3/4) -> 157 | H21: =INT(($G$1+IF($I$1>=1,IF($I$1=2,(INT($E$1/5)*2+70)+198,(INT($E$1/5)*2+10)+198),($E$1-1)*2))/SUM($C$26:$C$30)*VLOOKUP(F21,$S$28:$T$32,2)) -> 104 | I21: =SUMPRODUCT(($R$3:$R$7<=E21)*$S$3:$W$7*(F21=$S$2:$W$2)) -> 0 | J21: =IF(C21="是",VLOOKUP(F21,$T$12:$U$16,2),0) -> 0.8 | K21: =VLOOKUP(F21,$F$3:$K$7,6) -> 0.1 | L21: =IF(D21="是",0.1,0) -> 0 | M21: =IF(F21="防御",(N21/(1+L21+K21+J21+I21)/(((H21+G21)*1.2/资质数据!$C$42)+0.18)),(N21/(1+I21+J21+K21+L21)/(H21+G21)*VLOOKUP(F:F,资质数据!$B$37:$C$42,2)-B21*1.1)/1.2) -> 2332971.2 | N21: =VLOOKUP(F21,$F$3:$N$7,9) -> 5000000 | S21: 攻击 | T21: 2.07 | U21: 2 | V21: 1.74 | W21: 1.77 | X21: 4.22
B22: 1000 | C22: 是 | D22: 是 | E22: 0 | F22: 攻击 | G22: =IF(F22="防御",($E$1-1),$E$1-1+$G$1*3/4) -> 157 | H22: =INT(($G$1+IF($I$1>=1,IF($I$1=2,(INT($E$1/5)*2+70)+198,(INT($E$1/5)*2+10)+198),($E$1-1)*2))/SUM($C$26:$C$30)*VLOOKUP(F22,$S$28:$T$32,2)) -> #N/A | I22: =SUMPRODUCT(($R$3:$R$7<=E22)*$S$3:$W$7*(F22=$S$2:$W$2)) -> 0 | J22: =IF(C22="是",VLOOKUP(F22,$T$12:$U$16,2),0) -> #N/A | K22: =VLOOKUP(F22,$F$3:$K$7,6) -> #N/A | L22: =IF(D22="是",0.1,0) -> 0.1 | M22: =IF(F22="防御",(N22/(1+L22+K22+J22+I22)/(((H22+G22)*1.2/资质数据!$C$42)+0.18)),(N22/(1+I22+J22+K22+L22)/(H22+G22)*VLOOKUP(F:F,资质数据!$B$37:$C$42,2)-B22*1.1)/1.2) -> #N/A | N22: =VLOOKUP(F22,$F$3:$N$7,9) -> #N/A | S22: 速度 | T22: 3.31 | U22: 2.35 | V22: 2 | W22: 1.97 | X22: 8.14
B23: 1000 | C23: 否 | D23: 否 | E23: 0 | F23: 速度 | G23: =IF(F23="防御",($E$1-1),$E$1-1+$G$1*3/4) -> 157 | H23: =INT(($G$1+IF($I$1>=1,IF($I$1=2,(INT($E$1/5)*2+70)+198,(INT($E$1/5)*2+10)+198),($E$1-1)*2))/SUM($C$26:$C$30)*VLOOKUP(F23,$S$28:$T$32,2)) -> 27 | I23: =SUMPRODUCT(($R$3:$R$7<=E23)*$S$3:$W$7*(F23=$S$2:$W$2)) -> 0 | J23: =IF(C23="是",VLOOKUP(F23,$T$12:$U$16,2),0) -> 0 | K23: =VLOOKUP(F23,$F$3:$K$7,6) -> 0 | L23: =IF(D23="是",0.1,0) -> 0 | M23: =IF(F23="防御",(N23/(1+L23+K23+J23+I23)/(((H23+G23)*1.2/资质数据!$C$42)+0.18)),(N23/(1+I23+J23+K23+L23)/(H23+G23)*VLOOKUP(F:F,资质数据!$B$37:$C$42,2)-B23*1.1)/1.2) -> 124884.96 | N23: =VLOOKUP(F23,$F$3:$N$7,9) -> 100000 | S23: 法力 | T23: 3.07 | U23: 2.3 | V23: 2.04 | W23: 2 | X23: 7.25
B24: 1000 | C24: 否 | D24: 否 | E24: 0 | F24: 法力 | G24: =IF(F24="防御",($E$1-1),$E$1-1+$G$1*3/4) -> 157 | H24: =INT(($G$1+IF($I$1>=1,IF($I$1=2,(INT($E$1/5)*2+70)+198,(INT($E$1/5)*2+10)+198),($E$1-1)*2))/SUM($C$26:$C$30)*VLOOKUP(F24,$S$28:$T$32,2)) -> #N/A | I24: =SUMPRODUCT(($R$3:$R$7<=E24)*$S$3:$W$7*(F24=$S$2:$W$2)) -> 0 | J24: =IF(C24="是",VLOOKUP(F24,$T$12:$U$16,2),0) -> 0 | K24: =VLOOKUP(F24,$F$3:$K$7,6) -> #N/A | L24: =IF(D24="是",0.1,0) -> 0 | M24: =IF(F24="防御",(N24/(1+L24+K24+J24+I24)/(((H24+G24)*1.2/资质数据!$C$42)+0.18)),(N24/(1+I24+J24+K24+L24)/(H24+G24)*VLOOKUP(F:F,资质数据!$B$37:$C$42,2)-B24*1.1)/1.2) -> #N/A | N24: =VLOOKUP(F24,$F$3:$N$7,9) -> #N/A | S24: 防御 | T24: 1.5 | U24: 1.31 | V24: 1.14 | W24: 1.16 | X24: 2
B25: 1000 | C25: 是 | D25: 否 | E25: 1 | F25: 防御 | G25: =IF(F25="防御",($E$1-1),$E$1-1+$G$1*3/4) -> 82 | H25: =$G$1+IF($I$1>=1,IF($I$1=2,(INT($E$1/5)*2+70)+198,(INT($E$1/5)*2+10)+198),($E$1-1)*2)-H21-H22-H23-H24 -> #N/A | I25: =SUMPRODUCT(($R$3:$R$7<=E25)*$S$3:$W$7*(F25=$S$2:$W$2)) -> 0.36 | J25: =IF(C25="是",VLOOKUP(F25,$T$12:$U$16,2),0) -> #N/A | K25: =VLOOKUP(F25,$F$3:$K$7,6) -> #N/A | L25: =IF(D25="是",0.1,0) -> 0 | M25: =IF(F25="防御",(N25/(1+L25+K25+J25+I25)/(((H25+G25)*1.2/资质数据!$C$42)+0.18)),(N25/(1+I25+J25+K25+L25)/(H25+G25)*VLOOKUP(F:F,资质数据!$B$37:$C$42,2)-B25*1.1)/1.2) -> #N/A | N25: =VLOOKUP(F25,$F$3:$N$7,9) -> #N/A
A26: 三满/四满/五满属性点分配占比调整（随便调，会按数值比例去分配属性点） | B26: 生命 | C26: 180
B27: 攻击 | C27: 123
B28: 速度 | C28: 47 | S28: 生命 | T28: =C26 -> 180
B29: 法力 | C29: 41 | S29: 攻击 | T29: =C27 -> 123
B30: 防御 | C30: 297 | S30: 速度 | T30: =C28 -> 47
S31: 法力 | T31: =C29 -> 41
S32: 防御 | T32: =C30 -> 297

Sheet 提资计算表
A2: 宠物基础资质 | B2: 八四光年 | C2: 熊猫武圣
A3: 生命资质 | B3: 2626 | C3: 3656 | F3: 提资总结：做单满攻，提四合攻恶魔武士最省钱（孔多可适当用硬提八四光年替代，更省）；双满血防，硬提熊猫武圣九提一最省钱；三满攻血防，合攻二合树骑，三合熊猫大象提血防，最后四合宠九提一最省钱（孔多适当用硬提熊猫九提一替代更省）；五满四合a类提血防九提一（资质数据表表8）最省钱（10孔刚好百级五满，没得选）。 | T3: =C21 -> 自定义2 | U3: =C22 -> 三合攻熊猫 | V3: =C23 -> 三合攻熊猫 | W3: =C24 -> 三合攻熊猫 | X3: =C25 -> 三合攻巨象 | Y3: =C26 -> 三合攻巨象 | Z3: =C27 -> 自定义2 | AA3: =C28 -> 自定义2 | AB3: =C29 -> 自定义2 | AC3: =C30 | AD3: 合计 | AE3: 宝石 | AH3: 总和
A4: 攻击资质 | B4: 4333 | C4: 3383 | S4: 生命资质 | T4: =SUMPRODUCT(($A$9:$A$13=$S4)*$B$9:$Q$13*($B$8:$Q$8=T$3)) -> 2991 | U4: =SUMPRODUCT(($A$9:$A$13=$S4)*$B$9:$Q$13*($B$8:$Q$8=U$3)) -> 2056 | V4: =SUMPRODUCT(($A$9:$A$13=$S4)*$B$9:$Q$13*($B$8:$Q$8=V$3)) -> 2056 | W4: =SUMPRODUCT(($A$9:$A$13=$S4)*$B$9:$Q$13*($B$8:$Q$8=W$3)) -> 2056 | X4: =SUMPRODUCT(($A$9:$A$13=$S4)*$B$9:$Q$13*($B$8:$Q$8=X$3)) -> 2131 | Y4: =SUMPRODUCT(($A$9:$A$13=$S4)*$B$9:$Q$13*($B$8:$Q$8=Y$3)) -> 2131 | Z4: =SUMPRODUCT(($A$9:$A$13=$S4)*$B$9:$Q$13*($B$8:$Q$8=Z$3)) -> 2991 | AA4: =SUMPRODUCT(($A$9:$A$13=$S4)*$B$9:$Q$13*($B$8:$Q$8=AA$3)) -> 2991 | ... AC4: =SUMPRODUCT(($A$9:$A$13=$S4)*$B$9:$Q$13*($B$8:$Q$8=AC$3)) -> 0 | AD4: =SUM(T4:AC4) -> 22394 | AE4: =COUNTIF($D$21:$D$30,A15) -> 4 | AF4: =B15 -> 2406 | AG4: =AE4*AF4 -> 9624 | AH4: =AD4+AG4 -> 32018
A5: 速度资质 | B5: 2645 | C5: 2166 | S5: 攻击资质 | T5: =SUMPRODUCT(($A$9:$A$13=$S5)*$B$9:$Q$13*($B$8:$Q$8=T$3)) -> 3708 | U5: =SUMPRODUCT(($A$9:$A$13=$S5)*$B$9:$Q$13*($B$8:$Q$8=U$3)) -> 3555 | V5: =SUMPRODUCT(($A$9:$A$13=$S5)*$B$9:$Q$13*($B$8:$Q$8=V$3)) -> 3555 | W5: =SUMPRODUCT(($A$9:$A$13=$S5)*$B$9:$Q$13*($B$8:$Q$8=W$3)) -> 3555 | X5: =SUMPRODUCT(($A$9:$A$13=$S5)*$B$9:$Q$13*($B$8:$Q$8=X$3)) -> 3705 | Y5: =SUMPRODUCT(($A$9:$A$13=$S5)*$B$9:$Q$13*($B$8:$Q$8=Y$3)) -> 3705 | Z5: =SUMPRODUCT(($A$9:$A$13=$S5)*$B$9:$Q$13*($B$8:$Q$8=Z$3)) -> 3708 | AA5: =SUMPRODUCT(($A$9:$A$13=$S5)*$B$9:$Q$13*($B$8:$Q$8=AA$3)) -> 3708 | ... AC5: =SUMPRODUCT(($A$9:$A$13=$S5)*$B$9:$Q$13*($B$8:$Q$8=AC$3)) -> 0 | AD5: =SUM(T5:AC5) -> 32907 | AE5: =COUNTIF($D$21:$D$30,A16) -> 0 | AF5: =B16 -> 3589 | AG5: =AE5*AF5 -> 0 | AH5: =AD5+AG5 -> 32907
A6: 法力资质 | B6: 2569 | C6: 1347 | S6: 速度资质 | T6: =SUMPRODUCT(($A$9:$A$13=$S6)*$B$9:$Q$13*($B$8:$Q$8=T$3)) -> 19173 | U6: =SUMPRODUCT(($A$9:$A$13=$S6)*$B$9:$Q$13*($B$8:$Q$8=U$3)) -> 11500 | V6: =SUMPRODUCT(($A$9:$A$13=$S6)*$B$9:$Q$13*($B$8:$Q$8=V$3)) -> 11500 | W6: =SUMPRODUCT(($A$9:$A$13=$S6)*$B$9:$Q$13*($B$8:$Q$8=W$3)) -> 11500 | X6: =SUMPRODUCT(($A$9:$A$13=$S6)*$B$9:$Q$13*($B$8:$Q$8=X$3)) -> 11354 | Y6: =SUMPRODUCT(($A$9:$A$13=$S6)*$B$9:$Q$13*($B$8:$Q$8=Y$3)) -> 11354 | Z6: =SUMPRODUCT(($A$9:$A$13=$S6)*$B$9:$Q$13*($B$8:$Q$8=Z$3)) -> 19173 | AA6: =SUMPRODUCT(($A$9:$A$13=$S6)*$B$9:$Q$13*($B$8:$Q$8=AA$3)) -> 19173 | ... AC6: =SUMPRODUCT(($A$9:$A$13=$S6)*$B$9:$Q$13*($B$8:$Q$8=AC$3)) -> 0 | AD6: =SUM(T6:AC6) -> 133900 | AE6: =COUNTIF($D$21:$D$30,A17) -> 0 | AF6: =B17 -> 3042 | AG6: =AE6*AF6 -> 0 | AH6: =AD6+AG6 -> 133900
A7: 防御资质 | B7: 1352 | C7: 2977 | S7: 法力资质 | T7: =SUMPRODUCT(($A$9:$A$13=$S7)*$B$9:$Q$13*($B$8:$Q$8=T$3)) -> 10687 | U7: =SUMPRODUCT(($A$9:$A$13=$S7)*$B$9:$Q$13*($B$8:$Q$8=U$3)) -> 7611 | V7: =SUMPRODUCT(($A$9:$A$13=$S7)*$B$9:$Q$13*($B$8:$Q$8=V$3)) -> 7611 | W7: =SUMPRODUCT(($A$9:$A$13=$S7)*$B$9:$Q$13*($B$8:$Q$8=W$3)) -> 7611 | X7: =SUMPRODUCT(($A$9:$A$13=$S7)*$B$9:$Q$13*($B$8:$Q$8=X$3)) -> 7763 | Y7: =SUMPRODUCT(($A$9:$A$13=$S7)*$B$9:$Q$13*($B$8:$Q$8=Y$3)) -> 7763 | Z7: =SUMPRODUCT(($A$9:$A$13=$S7)*$B$9:$Q$13*($B$8:$Q$8=Z$3)) -> 10687 | AA7: =SUMPRODUCT(($A$9:$A$13=$S7)*$B$9:$Q$13*($B$8:$Q$8=AA$3)) -> 10687 | ... AC7: =SUMPRODUCT(($A$9:$A$13=$S7)*$B$9:$Q$13*($B$8:$Q$8=AC$3)) -> 0 | AD7: =SUM(T7:AC7) -> 81107 | AE7: =COUNTIF($D$21:$D$30,A18) -> 0 | AF7: =B18 -> 2365 | AG7: =AE7*AF7 -> 0 | AH7: =AD7+AG7 -> 81107
A8: 宠物资质宝石 | B8: 四合攻a类 | C8: 四合攻b类 | D8: 四合攻深渊领主 | E8: 四合攻恶魔武士 | F8: 四合速a类 | G8: 四合速b类 | H8: 四合速深渊领主 | I8: 四合速恶魔武士 | J8: 硬提八四光年 | K8: 硬提熊猫武圣 | L8: 二合攻树骑 | M8: 三合攻巨象 | N8: 三合攻熊猫 | O8: 自定义1 | P8: 自定义2 | Q8: 自定义3 | S8: 防御资质 | T8: =SUMPRODUCT(($A$9:$A$13=$S8)*$B$9:$Q$13*($B$8:$Q$8=T$3)) -> 3776 | U8: =SUMPRODUCT(($A$9:$A$13=$S8)*$B$9:$Q$13*($B$8:$Q$8=U$3)) -> 3011 | V8: =SUMPRODUCT(($A$9:$A$13=$S8)*$B$9:$Q$13*($B$8:$Q$8=V$3)) -> 3011 | W8: =SUMPRODUCT(($A$9:$A$13=$S8)*$B$9:$Q$13*($B$8:$Q$8=W$3)) -> 3011 | X8: =SUMPRODUCT(($A$9:$A$13=$S8)*$B$9:$Q$13*($B$8:$Q$8=X$3)) -> 2788 | Y8: =SUMPRODUCT(($A$9:$A$13=$S8)*$B$9:$Q$13*($B$8:$Q$8=Y$3)) -> 2788 | Z8: =SUMPRODUCT(($A$9:$A$13=$S8)*$B$9:$Q$13*($B$8:$Q$8=Z$3)) -> 3776 | AA8: =SUMPRODUCT(($A$9:$A$13=$S8)*$B$9:$Q$13*($B$8:$Q$8=AA$3)) -> 3776 | ... AC8: =SUMPRODUCT(($A$9:$A$13=$S8)*$B$9:$Q$13*($B$8:$Q$8=AC$3)) -> 0 | AD8: =SUM(T8:AC8) -> 29713 | AE8: =COUNTIF($D$21:$D$30,A19) -> 1 | AF8: =B19 -> 2400 | AG8: =AE8*AF8 -> 2400 | AH8: =AD8+AG8 -> 32113
A9: 生命资质 | B9: =资质数据!C29 -> 2078 | C9: =资质数据!D29 -> 2154 | D9: =资质数据!C4 -> 2106 | E9: =资质数据!H18 -> 2046 | F9: =资质数据!C29 -> 2078 | G9: =资质数据!D29 -> 2154 | H9: =资质数据!C4 -> 2106 | I9: =资质数据!H18 -> 2046 | J9: =B3*1.1/2 -> 1444.3 | K9: =C3*1.1/2 -> 2010.8 | L9: 2123 | M9: 2131 | N9: 2056 | O9: 15871.4 | P9: =综合计算器!L14 -> 2991 | Q9: =综合计算器!L14 -> 2991
A10: 攻击资质 | B10: =资质数据!C30 -> 4088.3333 | C10: =资质数据!D30 -> 3866.7778 | D10: =资质数据!C5 -> 4563 | E10: =资质数据!H19 -> 5472 | F10: =资质数据!C30-资质数据!$K$20 -> 3661.3333 | G10: =资质数据!D30-资质数据!$K$20 -> 3439.7778 | H10: =资质数据!C5-资质数据!$K$20 -> 4136 | I10: =资质数据!H19-资质数据!$K$20 -> 5045 | J10: =B4*1.1/2 -> 2383.15 | K10: =C4*1.1/2 -> 1860.65 | L10: 2783 | M10: 3705 | N10: 3555 | O10: 10233.575 | P10: =综合计算器!L15 -> 3708 | Q10: =综合计算器!L15 -> 3708 | V10: 载体 | W10: =I21 -> 四合攻恶魔武士 | X10: 红色资 | Y10: =I21 -> 四合攻恶魔武士
A11: 速度资质 | B11: =资质数据!C31 -> 15895.667 | C11: =资质数据!D31 -> 15872.556 | D11: =资质数据!C6 -> 15708 | E11: =资质数据!H20 -> 15250 | F11: =资质数据!C31+资质数据!$K$21 -> 18749.667 | G11: =资质数据!D31+资质数据!$K$21 -> 18726.556 | H11: =资质数据!C6+资质数据!$K$21 -> 18562 | I11: =资质数据!H20+资质数据!$K$21 -> 18104 | J11: =B5*1.1/2 -> 1454.75 | K11: =C5*1.1/2 -> 1191.3 | L11: 7979 | M11: 11354 | N11: 11500 | O11: 6552.15 | P11: =综合计算器!L16 -> 19173 | Q11: =综合计算器!L16 -> 19173 | V11: 生命资质 | W11: =SUMPRODUCT(($A$9:$A$13=V11)*$B$9:$P$13*($B$8:$P$8=$W$10)) -> 2046 | X11: =AH4 -> 32018 | Y11: =SUMPRODUCT(($A$9:$A$13=$V11)*$L$9:$Q$13*($L$8:$Q$8=Y$10))*1.1/2 -> 0 | Z11: =X11/2+Y11+W11 -> 18055
A12: 法力资质 | B12: =资质数据!C32 -> 10837.333 | C12: =资质数据!D32 -> 11007.111 | D12: =资质数据!C7 -> 10527 | E12: =资质数据!H21 -> 11138 | F12: =资质数据!C32 -> 10837.333 | G12: =资质数据!D32 -> 11007.111 | H12: =资质数据!C7 -> 10527 | I12: =资质数据!H21 -> 11138 | J12: =B6*1.1/2 -> 1412.95 | K12: =C6*1.1/2 -> 740.85 | L12: 5291 | M12: 7763 | N12: 7611 | O12: 4074.675 | P12: =综合计算器!L17 -> 10687 | Q12: =综合计算器!L17 -> 10687 | V12: 攻击资质 | W12: =SUMPRODUCT(($A$9:$A$13=V12)*$B$9:$P$13*($B$8:$P$8=$W$10)) -> 5472 | X12: =AH5 -> 32907 | Y12: =SUMPRODUCT(($A$9:$A$13=$V12)*$L$9:$Q$13*($L$8:$Q$8=Y$10))*1.1/2 -> 0 | Z12: =X12/2+Y12+W12 -> 21925.5
A13: 防御资质 | B13: =资质数据!C33 -> 2686 | C13: =资质数据!D33 -> 2686 | D13: =资质数据!C8 -> 2686 | E13: =资质数据!H22 -> 2777 | F13: =资质数据!C33 -> 2686 | G13: =资质数据!D33 -> 2686 | H13: =资质数据!C8 -> 2686 | I13: =资质数据!H22 -> 2777 | J13: =B7*1.1/2 -> 743.6 | K13: =C7*1.1/2 -> 1637.35 | L13: 2186 | M13: 2788 | N13: 3011 | O13: 15005.425 | P13: =综合计算器!L18 -> 3776 | Q13: =综合计算器!L18 -> 3776 | V13: 速度资质 | W13: =SUMPRODUCT(($A$9:$A$13=V13)*$B$9:$P$13*($B$8:$P$8=$W$10)) -> 15250 | X13: =AH6 -> 133900 | Y13: =SUMPRODUCT(($A$9:$A$13=$V13)*$L$9:$Q$13*($L$8:$Q$8=Y$10))*1.1/2 -> 0 | Z13: =X13/2+Y13+W13 -> 82200
A14: 提资类型 | B14: 8+3 | V14: 法力资质 | W14: =SUMPRODUCT(($A$9:$A$13=V14)*$B$9:$P$13*($B$8:$P$8=$W$10)) -> 11138 | X14: =AH7 -> 81107 | Y14: =SUMPRODUCT(($A$9:$A$13=$V14)*$L$9:$Q$13*($L$8:$Q$8=Y$10))*1.1/2 -> 0 | Z14: =X14/2+Y14+W14 -> 51691.5
A15: 生命 | B15: =资质数据!C11 -> 2406 | D15: 注释： ①计算出资质总和可用于前表计算器算属性； ②自定义1和自定义2用于填写其他类型资质宝石，例如宰宠或瞎几把提（此时不需要选择提资方向）； ③自定义3用于其他类型的多提一载体，例如打在百变魔女等可交易宠上做交易资； ④下表多孔资质宝石可自由填写，可以选择填7孔（普通宠和活动宠例如北极宠），可选择填9孔（神兽以上），可选择10孔（绝世及10孔野），可直接用于计算最终资质，也可进一步计算提出有多少资质（做多提一资质宝石）； 其他：八四光年硬提攻资收益（单位rmb得出资质）比自合高25%，熊猫硬提血防同样高25%，缺点是不做多提一占孔过多，用于补资是优选。 | L15: 简易提资计算 | M15: 宠物基础 | N15: 红色资质 | O15: 提出资质 | V15: 防御资质 | W15: =SUMPRODUCT(($A$9:$A$13=V15)*$B$9:$P$13*($B$8:$P$8=$W$10)) -> 2777 | X15: =AH8 -> 32113 | Y15: =SUMPRODUCT(($A$9:$A$13=$V15)*$L$9:$Q$13*($L$8:$Q$8=Y$10))*1.1/2 -> 0 | Z15: =X15/2+Y15+W15 -> 18833.5
A16: 攻击 | B16: =资质数据!C12 -> 3589 | L16: 生命资质 | M16: 1683 | N16: 63859 | O16: =N16/2+M16*1.1/2 -> 32855.15
A17: 速度 | B17: =资质数据!C13 -> 3042 | L17: 攻击资质 | M17: 647 | N17: 50025 | O17: =N17/2+M17*1.1/2 -> 25368.35
A18: 法力 | B18: =430*11/2 -> 2365 | L18: 速度资质 | M18: 895 | N18: 139333 | O18: =N18/2+M18*1.1/2 -> 70158.75
A19: 防御 | B19: =资质数据!C15 -> 2400 | L19: 法力资质 | M19: 2000 | N19: 81166 | O19: =N19/2+M19*1.1/2 -> 41683
A20: 资质计算器 | B20: 孔位 | C20: 资质宝石选择 | D20: 提资方向 | E20: 计算得出资质总和 | H20: 将左侧宠物资质再提出 | L20: 防御资质 | M20: 1230 | N20: 65158 | O20: =N20/2+M20*1.1/2 -> 33255.5
B21: 第一孔 | C21: 自定义2 | E21: 生命资质 | F21: =AH4 -> 32018 | H21: 载体选择 | I21: 四合攻恶魔武士
B22: 第二孔 | C22: 三合攻熊猫 | D22: 生命 | E22: 攻击资质 | F22: =AH5 -> 32907 | H22: 资质宝石
B23: 第三孔 | C23: 三合攻熊猫 | D23: 生命 | E23: 速度资质 | F23: =AH6 -> 133900 | H23: 生命资质 | I23: =Z11 -> 18055
B24: 第四孔 | C24: 三合攻熊猫 | D24: 生命 | E24: 法力资质 | F24: =AH7 -> 81107 | H24: 攻击资质 | I24: =Z12 -> 21925.5
B25: 第五孔 | C25: 三合攻巨象 | D25: 生命 | E25: 防御资质 | F25: =AH8 -> 32113 | H25: 速度资质 | I25: =Z13 -> 82200
B26: 第六孔 | C26: 三合攻巨象 | D26: 防御 | H26: 法力资质 | I26: =Z14 -> 51691.5
B27: 第七孔 | C27: 自定义2 | H27: 防御资质 | I27: =Z15 -> 18833.5
B28: 第八孔 | C28: 自定义2
B29: 第九孔 | C29: 自定义2
B30: 第十孔

Sheet 从零开始做资参考
B2: 前言：本数据表为从零出发以最高性价比的方式（除宰伤心退游资外）做出能在有限孔位下达成目标属性的资质，所以存在多种资质混合的情况。 以下均以九孔宠为基底，增幅贴纸可以打四张（满血防按五贴算，满血防还能上防腰带披风），留一个位置打逆流（双满血防忽略）。 40级以下玩家没有家族五石及战神资，建议做可交易宠在小号上做资。 以下资质再加上宠物基础资质就会属性溢出，刚好作为进化分配点数不平均的修正（就当以下数据是估高了即可）。 材料栏只列出需要花钱的部分 | I2: 九提一参考往右边拉过去>
B3: 38组（宠物43级） | G3: 48组（宠物53级） | L3: 58组（宠物63级） | Q3: 78组（宠物83级） | V3: 100组（宠物100级）
B4: 单满速 | C4: 需要资质 | D4: 154000 | E4: 圣迅捷及速度法宝 | G4: 单满速 | H4: 需要资质 | I4: 149500 | J4: 圣迅捷及速度法宝 | L4: 单满速 | M4: 需要资质 | N4: 145000 | O4: 圣迅捷及速度法宝 | Q4: 单满速 | R4: 需要资质 | S4: 138200 | T4: 圣迅捷及速度法宝 | V4: 单满速 | W4: 需要资质 | X4: 132200 | Y4: 圣迅捷及速度法宝
B5: 说明：9孔野宠也能轻松达到这个资质需求，在不投入圣迅捷转而使用迅捷b也只需要183000的速度资质，此时需要做第九孔资，并且要有五颗提速度（肥料前途：建议四合提资的时候更多的去提血防，为了节省家族贡献，可以只打上攻速防家族资进行合宠） | G5: 说明：9孔野宠也能轻松达到这个资质需求，在不投入圣迅捷转而使用迅捷b也只需要178000的速度资质，此时需要做到第九孔资，并且要有四颗提速度（肥料前途：建议四合提资的时候更多的去提血防，为了节省家族贡献，可以只打上攻速防家族资进行合宠） | L5: 说明：9孔野宠也能轻松达到这个资质需求，在不投入圣迅捷转而使用迅捷b也只需要172600的速度资质，此时需要做到第八孔资，并且要有八颗提速度（肥料前途：建议四合提资的时候更多的去提血防，为了节省家族贡献，可以只打上攻速防家族资进行合宠） | Q5: 说明：9孔野宠也能轻松达到这个资质需求，在不投入圣迅捷转而使用迅捷b也只需要164000的速度资质，此时需要做到第八孔资，并且要有五颗提速度（肥料前途：建议四合提资的时候更多的去提血防，为了节省家族贡献，可以只打上攻速防家族资进行合宠） | V5: 说明：9孔野宠也能轻松达到这个资质需求，在不投入圣迅捷转而使用迅捷b也只需要158000的速度资质，此时需要做到第八孔资，并且要有三颗提速度（肥料前途：建议四合提资的时候更多的去提血防，为了节省家族贡献，可以只打上攻速防家族资进行合宠）
B6: 孔位 | C6: 资质宝石选择 | D6: 提资方向 | E6: 计算得出资质总和 | G6: 孔位 | H6: 资质宝石选择 | I6: 提资方向 | J6: 计算得出资质总和 | L6: 孔位 | M6: 资质宝石选择 | N6: 提资方向 | O6: 计算得出资质总和 | Q6: 孔位 | R6: 资质宝石选择 | S6: 提资方向 | T6: 计算得出资质总和 | V6: 孔位 | W6: 资质宝石选择 | X6: 提资方向 | Y6: 计算得出资质总和 | AD6: 四合速提攻九提一 | AE6: 孔位 | AF6: 资质宝石选择 | AG6: 提资方向 | AH6: 计算得出资质总和 | AJ6: 将左侧宠物资质再提出
B7: 第一孔 | C7: 四合速a类 | D7: 防御 | E7: 生命资质 | F7: 21436 | G7: 第一孔 | H7: 四合速a类 | I7: 防御 | J7: 生命资质 | K7: 14546 | L7: 第一孔 | M7: 四合速a类 | N7: 防御 | O7: 生命资质 | P7: 14546 | Q7: 第一孔 | R7: 四合速a类 | S7: 生命 | T7: 生命资质 | U7: 16952 | V7: 第一孔 | W7: 四合速a类 | X7: 生命 | Y7: 生命资质 | Z7: 21764 | AE7: 第一孔 | AF7: 四合速a类 | AG7: 攻击 | AH7: 生命资质 | AI7: 18702 | AJ7: 载体选择 | AK7: 四合速a类
B8: 第二孔 | C8: 四合速a类 | D8: 防御 | E8: 攻击资质 | F8: 29290.667 | G8: 第二孔 | H8: 四合速a类 | I8: 速度 | J8: 攻击资质 | K8: 25629.333 | L8: 第二孔 | M8: 四合速a类 | N8: 防御 | O8: 攻击资质 | P8: 25629.333 | Q8: 第二孔 | R8: 四合速a类 | S8: 速度 | T8: 攻击资质 | U8: 25629.333 | V8: 第二孔 | W8: 四合速a类 | X8: 生命 | Y8: 攻击资质 | Z8: 25629.333 | AE8: 第二孔 | AF8: 四合速a类 | AG8: 攻击 | AH8: 攻击资质 | AI8: 65253 | AJ8: 资质宝石（披风3攻）
B9: 第三孔 | C9: 四合速a类 | D9: 防御 | E9: 速度资质 | F9: 156081.33 | G9: 第三孔 | H9: 四合速a类 | I9: 速度 | J9: 速度资质 | K9: 149499.67 | L9: 第三孔 | M9: 四合速a类 | N9: 速度 | O9: 速度资质 | P9: 146457.67 | Q9: 第三孔 | R9: 四合速a类 | S9: 速度 | T9: 速度资质 | U9: 140373.67 | V9: 第三孔 | W9: 四合速a类 | X9: 生命 | Y9: 速度资质 | Z9: 134289.67 | AE9: 第三孔 | AF9: 四合速a类 | AG9: 攻击 | AH9: 速度资质 | AI9: 168747 | AJ9: 生命资质 | AK9: 11429
B10: 第四孔 | C10: 四合速a类 | D10: 防御 | E10: 法力资质 | F10: 86698.667 | G10: 第四孔 | H10: 四合速a类 | I10: 速度 | J10: 法力资质 | K10: 75861.333 | L10: 第四孔 | M10: 四合速a类 | N10: 速度 | O10: 法力资质 | P10: 75861.333 | Q10: 第四孔 | R10: 四合速a类 | S10: 速度 | T10: 法力资质 | U10: 75861.333 | V10: 第四孔 | W10: 四合速a类 | X10: 速度 | Y10: 法力资质 | Z10: 75861.333 | AE10: 第四孔 | AF10: 四合速a类 | AG10: 攻击 | AH10: 法力资质 | AI10: 97536 | AJ10: 攻击资质 | AK10: 37265.833
B11: 第五孔 | C11: 四合速a类 | D11: 速度 | E11: 防御资质 | F11: 31088 | G11: 第五孔 | H11: 四合速a类 | I11: 速度 | J11: 防御资质 | K11: 21202 | L11: 第五孔 | M11: 四合速a类 | N11: 速度 | O11: 防御资质 | P11: 23602 | Q11: 第五孔 | R11: 四合速a类 | S11: 防御 | T11: 防御资质 | U11: 26002 | V11: 第五孔 | W11: 四合速a类 | X11: 防御 | Y11: 防御资质 | Z11: 26002 | AE11: 第五孔 | AF11: 四合速a类 | AG11: 攻击 | AH11: 防御资质 | AI11: 24174 | AJ11: 速度资质 | AK11: 103123.17
B12: 第六孔 | C12: 四合速a类 | D12: 速度 | G12: 第六孔 | H12: 四合速a类 | I12: 速度 | L12: 第六孔 | M12: 四合速a类 | N12: 速度 | Q12: 第六孔 | R12: 四合速a类 | S12: 防御 | V12: 第六孔 | W12: 四合速a类 | X12: 防御 | AE12: 第六孔 | AF12: 四合速a类 | AG12: 攻击 | AJ12: 法力资质 | AK12: 59605.333
B13: 第七孔 | C13: 四合速a类 | D13: 生命 | G13: 第七孔 | H13: 四合速a类 | I13: 速度 | L13: 第七孔 | M13: 四合速a类 | N13: 速度 | Q13: 第七孔 | R13: 四合速a类 | S13: 防御 | V13: 第七孔 | W13: 四合速a类 | X13: 防御 | AE13: 第七孔 | AF13: 四合速a类 | AG13: 攻击 | AJ13: 防御资质 | AK13: 14773
B14: 第八孔 | C14: 四合速a类 | D14: 生命 | G14: 第八孔 | L14: 第八孔 | Q14: 第八孔 | V14: 第八孔 | AE14: 第八孔 | AF14: 四合速a类 | AG14: 攻击
B15: 第九孔 | G15: 第九孔 | L15: 第九孔 | Q15: 第九孔 | V15: 第九孔 | AE15: 第九孔 | AF15: 四合速a类 | AG15: 攻击
B16: 材料：提资器*8，合成石*32，普通披风*8，魔族五石*66，家族贡献172000–704000，战神高级积分8000000 | G16: 材料：提资器*7，合成石*28，普通披风*7，魔族五石*11，家族贡献154000–616000，战神高级积分7000000 | L16: 材料：提资器*7，合成石*28，普通披风*7，魔族五石*22，家族贡献154000–616000，战神高级积分7000000 | Q16: 材料：提资器*7，合成石*28，普通披风*7，魔族五石*33，家族贡献154000–616000，战神高级积分7000000 | V16: 材料：提资器*7，合成石*28，普通披风*7，魔族五石*66，家族贡献154000–616000，战神高级积分7000000
B17: 38组（宠物43级） | G17: 48组（宠物53级） | L17: 58组（宠物63级） | Q17: 78组（宠物83级） | V17: 100组（宠物100级）
B18: 单满攻 | C18: 需要资质 | D18: 91000 | E18: 圣强力及攻击法宝 | G18: 单满攻 | H18: 需要资质 | I18: 88500 | J18: 圣强力及攻击法宝 | L18: 单满攻 | M18: 需要资质 | N18: 86200 | O18: 圣强力及攻击法宝 | Q18: 单满攻 | R18: 需要资质 | S18: 81900 | T18: 圣强力及攻击法宝 | V18: 单满攻 | W18: 需要资质 | X18: 78300 | Y18: 圣强力及攻击法宝
B19: 说明：满攻开始比较费钱了，圣强力必打，如果不打圣强力需要继续投入数倍圣强力的rmb补资，十孔野用四合攻恶魔武士直接堆满即可（需要五个完美启多打一颗五品攻击宝石），算上十孔野本身的价值，投入比九孔省50左右，有条件建议上十孔野更有性价比（肥料前途：建议四合提资的时候更多的去提血防，为了节省家族贡献，可以只打上攻防家族资进行合宠） | G19: 说明：满攻开始比较费钱了，圣强力必打，如果不打圣强力需要继续投入数倍圣强力的rmb补资，十孔野用九孔四合攻恶魔武士和一孔四合攻即可，算上十孔野本身的价值，投入比九孔省50左右，有条件建议上十孔野更有性价比（肥料前途：建议四合提资的时候更多的去提血防，为了节省家族贡献，可以只打上攻防家族资进行合宠） | L19: 说明：满攻开始比较费钱了，圣强力必打，如果不打圣强力需要继续投入数倍圣强力的rmb补资，十孔野用七孔四合攻恶魔武士和三孔四合攻即可，算上十孔野本身的价值，投入比九孔省70左右，有条件建议上十孔野更有性价比（肥料前途：建议四合提资的时候更多的去提血防，为了节省家族贡献，可以只打上攻防家族资进行合宠） | Q19: 说明：满攻开始比较费钱了，圣强力必打，如果不打圣强力需要继续投入数倍圣强力的rmb补资（肥料前途：建议四合提资的时候更多的去提血防，为了节省家族贡献，可以只打上攻防家族资进行合宠） | V19: 说明：满攻开始比较费钱了，圣强力必打，如果不打圣强力需要继续投入数倍圣强力的rmb补资（肥料前途：建议四合提资的时候更多的去提血防，为了节省家族贡献，可以只打上攻防家族资进行合宠）
B20: 孔位 | C20: 资质宝石选择 | D20: 提资方向 | E20: 计算得出资质总和 | G20: 孔位 | H20: 资质宝石选择 | I20: 提资方向 | J20: 计算得出资质总和 | L20: 孔位 | M20: 资质宝石选择 | N20: 提资方向 | O20: 计算得出资质总和 | Q20: 孔位 | R20: 资质宝石选择 | S20: 提资方向 | T20: 计算得出资质总和 | V20: 孔位 | W20: 资质宝石选择 | X20: 提资方向 | Y20: 计算得出资质总和 | AD20: 硬提八四光年九提一 | AE20: 孔位 | AF20: 资质宝石选择 | AG20: 提资方向 | AH20: 计算得出资质总和 | AJ20: 将左侧宠物资质再提出
B21: 第一孔 | C21: 硬提八四光年九提一 | E21: 生命资质 | F21: 24595.65 | G21: 第一孔 | H21: 硬提八四光年九提一 | J21: 生命资质 | K21: 23933.95 | L21: 第一孔 | M21: 硬提八四光年九提一 | O21: 生命资质 | P21: 23300.25 | Q21: 第一孔 | R21: 四合攻恶魔武士 | S21: 攻击（完美启） | T21: 生命资质 | U21: 18414 | V21: 第一孔 | W21: 四合攻恶魔武士 | X21: 攻击 | Y21: 生命资质 | Z21: 18566 | AE21: 第一孔 | AF21: 硬提八四光年 | AG21: 攻击 | AH21: 生命资质 | AI21: 12998.7 | AJ21: 载体选择 | AK21: 硬提八四光年
B22: 第二孔 | C22: 四合攻a类 | D22: 攻击 | E22: 攻击资质 | F22: 91151.158 | G22: 第二孔 | H22: 四合攻a类 | I22: 攻击 | J22: 攻击资质 | K22: 88971.308 | L22: 第二孔 | M22: 四合攻a类 | N22: 攻击 | O22: 攻击资质 | P22: 87266.125 | Q22: 第二孔 | R22: 四合攻恶魔武士 | S22: 攻击（完美启） | T22: 攻击资质 | U22: 82202 | V22: 第二孔 | W22: 四合攻恶魔武士 | X22: 攻击 | Y22: 攻击资质 | Z22: 78347.333 | AE22: 第二孔 | AF22: 硬提八四光年 | AG22: 攻击 | AH22: 攻击资质 | AI22: 53749.35 | AJ22: 资质宝石（披风3攻）
B23: 第三孔 | C23: 四合攻a类 | D23: 攻击 | E23: 速度资质 | F23: 134978.79 | G23: 第三孔 | H23: 四合攻a类 | I23: 攻击 | J23: 速度资质 | K23: 120725.54 | L23: 第三孔 | M23: 四合攻a类 | N23: 攻击 | O23: 速度资质 | P23: 106284.62 | Q23: 第三孔 | R23: 四合攻恶魔武士 | S23: 攻击 | T23: 速度资质 | U23: 137250 | V23: 第三孔 | W23: 四合攻恶魔武士 | X23: 攻击 | Y23: 速度资质 | Z23: 138811.67 | AE23: 第三孔 | AF23: 硬提八四光年 | AG23: 攻击 | AH23: 速度资质 | AI23: 13092.75 | AJ23: 生命资质 | AK23: 7943.65
B24: 第四孔 | C24: 四合攻a类 | D24: 攻击 | E24: 法力资质 | F24: 94159.558 | G24: 第四孔 | H24: 四合攻a类 | I24: 攻击 | J24: 法力资质 | K24: 85045.508 | L24: 第四孔 | M24: 四合攻a类 | N24: 攻击 | O24: 法力资质 | P24: 75621.125 | Q24: 第四孔 | R24: 四合攻恶魔武士 | S24: 攻击 | T24: 法力资质 | U24: 100242 | V24: 第四孔 | W24: 四合攻恶魔武士 | X24: 攻击 | Y24: 法力资质 | Z24: 98719.333 | AE24: 第四孔 | AF24: 硬提八四光年 | AG24: 攻击 | AH24: 法力资质 | AI24: 12716.55 | AJ24: 攻击资质 | AK24: 30235.825
B25: 第五孔 | C25: 四合攻a类 | D25: 攻击 | E25: 防御资质 | F25: 25577.8 | G25: 第五孔 | H25: 四合攻a类 | I25: 攻击 | J25: 防御资质 | K25: 23635.4 | L25: 第五孔 | M25: 四合攻a类 | N25: 攻击 | O25: 防御资质 | P25: 21693 | Q25: 第五孔 | R25: 四合攻恶魔武士 | S25: 攻击 | T25: 防御资质 | U25: 24993 | V25: 第五孔 | W25: 四合攻恶魔武士 | X25: 攻击 | Y25: 防御资质 | Z25: 24720 | AE25: 第五孔 | AF25: 硬提八四光年 | AG25: 攻击 | AH25: 防御资质 | AI25: 6692.4 | AJ25: 速度资质 | AK25: 8001.125
B26: 第六孔 | C26: 四合攻a类 | D26: 攻击 | G26: 第六孔 | H26: 四合攻a类 | I26: 攻击 | L26: 第六孔 | M26: 四合攻a类 | N26: 攻击 | Q26: 第六孔 | R26: 四合攻恶魔武士 | S26: 攻击 | V26: 第六孔 | W26: 四合攻恶魔武士 | X26: 攻击 | AE26: 第六孔 | AF26: 硬提八四光年 | AG26: 攻击 | AJ26: 法力资质 | AK26: 7771.225
B27: 第七孔 | C27: 四合攻a类 | D27: 攻击 | G27: 第七孔 | H27: 四合攻a类 | I27: 攻击 | L27: 第七孔 | M27: 四合攻a类 | N27: 攻击 | Q27: 第七孔 | R27: 四合攻恶魔武士 | S27: 攻击 | V27: 第七孔 | W27: 四合攻深渊领主 | X27: 攻击 | AE27: 第七孔 | AF27: 硬提八四光年 | AG27: 攻击 | AJ27: 防御资质 | AK27: 4089.8
B28: 第八孔 | C28: 四合攻a类 | D28: 攻击 | G28: 第八孔 | H28: 四合攻a类 | I28: 攻击 | L28: 第八孔 | M28: 硬提八四光年 | N28: 攻击 | Q28: 第八孔 | R28: 四合攻恶魔武士 | S28: 攻击 | V28: 第八孔 | W28: 四合攻深渊领主 | X28: 攻击 | AE28: 第八孔 | AF28: 硬提八四光年 | AG28: 攻击
B29: 第九孔 | C29: 四合攻深渊领主 | D29: 攻击 | G29: 第九孔 | H29: 硬提八四光年 | I29: 攻击 | L29: 第九孔 | M29: 硬提八四光年 | N29: 攻击 | Q29: 第九孔 | R29: 四合攻恶魔武士 | S29: 攻击 | V29: 第九孔 | W29: 四合攻a类 | X29: 攻击 | AE29: 第九孔 | AF29: 硬提八四光年 | AG29: 攻击
B30: 材料：提资器*18，合成石*32，普通披风*18，完美启魂书*1，家族贡献172000–704000，战神高级积分10000000 | G30: 材料：提资器*18，合成石*28，普通披风*18，完美启魂书*1，家族贡献154000–616000，战神高级积分9200000 | L30: 材料：提资器*18，合成石*24，普通披风*18，完美启魂书*1，家族贡献132000–528000，战神高级积分8400000 | Q30: 材料：提资器*9，合成石*36，普通披风*9，完美启魂书*2，家族贡献198000–792000，战神高级积分9000000，珍奇宠召唤卷轴*9 | V30: 材料：提资器*9，合成石*36，普通披风*9，家族贡献198000–792000，战神高级积分9000000，珍奇宠召唤卷轴*6，ss召唤卷轴*2
B31: 38组（宠物43级） | G31: 48组（宠物53级） | L31: 58组（宠物63级） | Q31: 78组（宠物83级） | V31: 100组（宠物100级）
B32: 双满攻速 | C32: 需要资质 | D32: 155500 | E32: 322800 | F32: 圣强力圣迅捷及攻击法宝 | G32: 双满攻速 | H32: 需要资质 | I32: 145000 | J32: 326000 | K32: 圣强力圣迅捷及攻击法宝 | L32: 双满攻速 | M32: 需要资质 | N32: 133000 | O32: 332900 | P32: 圣强力圣迅捷及攻击法宝 | Q32: 双满攻速 | R32: 需要资质 | S32: 125000 | T32: 315000 | U32: 圣强力圣迅捷及攻击法宝 | V32: 双满攻速 | W32: 需要资质 | X32: 118000 | Y32: 300000 | Z32: 圣强力圣迅捷及攻击法宝
B33: 说明：满攻速纯玩具，应该没人做卡级双满攻速，必须要圣强力圣迅捷，如果换成速度法宝还需要再补小几千攻资，两攻贴两速贴达成双满，需要不少完美启（肥料前途：建议四合提资的时候更多的去提血防，为了节省家族贡献，可以只打上攻防家族资进行合宠） | G33: 说明：满攻速纯玩具，应该没人做卡级双满攻速，必须要圣强力圣迅捷，如果换成速度法宝还需要再补小几千攻资，两攻贴两速贴达成双满（肥料前途：建议四合提资的时候更多的去提血防，为了节省家族贡献，可以只打上攻防家族资进行合宠） | L33: 说明：满攻速纯玩具，应该没人做卡级双满攻速，必须要圣强力圣迅捷，如果换成速法宝还需要再补小几千攻资，两攻贴两速贴达成双满（肥料前途：建议四合提资的时候更多的去提血防，为了节省家族贡献，可以只打上攻防家族资进行合宠） | Q33: 说明：满攻速纯玩具，应该没人做卡级双满攻速，必须要圣强力圣迅捷，如果换成速法宝还需要再补小几千攻资，两攻贴两速贴达成双满（肥料前途：建议四合提资的时候更多的去提血防，为了节省家族贡献，可以只打上攻防家族资进行合宠） | V33: 说明：满攻速纯玩具，应该没人做卡级双满攻速，必须要圣强力圣迅捷，如果换成速法宝还需要再补小几千攻资，两攻贴两速贴达成双满（肥料前途：建议四合提资的时候更多的去提血防，为了节省家族贡献，可以只打上攻防家族资进行合宠）
B34: 孔位 | C34: 资质宝石选择 | D34: 提资方向 | E34: 计算得出资质总和 | G34: 孔位 | H34: 资质宝石选择 | I34: 提资方向 | J34: 计算得出资质总和 | L34: 孔位 | M34: 资质宝石选择 | N34: 提资方向 | O34: 计算得出资质总和 | Q34: 孔位 | R34: 资质宝石选择 | S34: 提资方向 | T34: 计算得出资质总和 | V34: 孔位 | W34: 资质宝石选择 | X34: 提资方向 | Y34: 计算得出资质总和 | AD34: 四合速深渊提攻九提一（深渊） | AE34: 孔位 | AF34: 资质宝石选择 | AG34: 提资方向 | AH34: 计算得出资质总和 | AJ34: 将左侧宠物资质再提出
B35: 第一孔 | C35: 四合速提攻九提一 | E35: 生命资质 | F35: 43077.65 | G35: 第一孔 | H35: 四合速提攻九提一 | J35: 生命资质 | K35: 43269.65 | L35: 第一孔 | M35: 四合速提攻九提一 | O35: 生命资质 | P35: 37180 | Q35: 第一孔 | R35: 四合速提攻九提一 | T35: 生命资质 | U35: 37404 | V35: 第一孔 | W35: 四合速提攻九提一 | Y35: 生命资质 | Z35: 35326 | AE35: 第一孔 | AF35: 四合速深渊领主 | AG35: 攻击 | AH35: 生命资质 | AI35: 18954 | AJ35: 载体选择 | AK35: 四合速深渊领主
B36: 第二孔 | C36: 四合速提攻九提一 | E36: 攻击资质 | F36: 155596.49 | G36: 第二孔 | H36: 四合速提攻九提一 | J36: 攻击资质 | K36: 145335.49 | L36: 第二孔 | M36: 四合速提攻九提一 | O36: 攻击资质 | P36: 133013.67 | Q36: 第二孔 | R36: 四合速提攻九提一 | T36: 攻击资质 | U36: 126317 | V36: 第二孔 | W36: 四合速提攻九提一 | Y36: 攻击资质 | Z36: 118639.67 | AE36: 第二孔 | AF36: 四合速深渊领主 | AG36: 攻击 | AH36: 攻击资质 | AI36: 69525 | AJ36: 资质宝石（披风3攻）
B37: 第三孔 | C37: 硬提八四光年九提一 | E37: 速度资质 | F37: 322871.46 | G37: 第三孔 | H37: 硬提八四光年九提一 | J37: 速度资质 | K37: 326745.46 | L37: 第三孔 | M37: 四合速恶魔武士 | N37: 攻击 | O37: 速度资质 | P37: 332974.33 | Q37: 第三孔 | R37: 四合攻a类 | S37: 攻击 | T37: 速度资质 | U37: 317516 | V37: 第三孔 | W37: 四合攻a类 | X37: 攻击 | Y37: 速度资质 | Z37: 301620.33 | AE37: 第三孔 | AF37: 四合速深渊领主 | AG37: 攻击 | AH37: 速度资质 | AI37: 167058 | AJ37: 生命资质 | AK37: 11583
B38: 第四孔 | C38: 四合速恶魔武士 | D38: 攻击（完美启） | E38: 法力资质 | F38: 193809.89 | G38: 第四孔 | H38: 四合速a类 | I38: 攻击 | J38: 法力资质 | K38: 192005.89 | L38: 第四孔 | M38: 四合速恶魔武士 | N38: 攻击 | O38: 法力资质 | P38: 197176.67 | Q38: 第四孔 | R38: 四合攻a类 | S38: 攻击 | T38: 法力资质 | U38: 195072 | V38: 第四孔 | W38: 四合攻a类 | X38: 攻击 | Y38: 法力资质 | Z38: 184234.67 | AE38: 第四孔 | AF38: 四合速深渊领主 | AG38: 攻击 | AH38: 法力资质 | AI38: 94743 | AJ38: 攻击资质 | AK38: 39876.5
B39: 第五孔 | C39: 四合速恶魔武士 | D39: 攻击（完美启） | E39: 防御资质 | F39: 50297.8 | G39: 第五孔 | H39: 四合速a类 | I39: 攻击 | J39: 防御资质 | K39: 49751.8 | L39: 第五孔 | M39: 四合速恶魔武士 | N39: 攻击 | O39: 防御资质 | P39: 48985 | Q39: 第五孔 | R39: 四合攻a类 | S39: 攻击 | T39: 防御资质 | U39: 48348 | V39: 第五孔 | W39: 四合攻a类 | X39: 攻击 | Y39: 防御资质 | Z39: 45662 | AE39: 第五孔 | AF39: 四合速深渊领主 | AG39: 攻击 | AH39: 防御资质 | AI39: 24174 | AJ39: 速度资质 | AK39: 102091
B40: 第六孔 | C40: 四合速恶魔武士 | D40: 攻击（完美启） | G40: 第六孔 | H40: 四合速a类 | I40: 攻击 | L40: 第六孔 | M40: 四合速恶魔武士 | N40: 攻击 | Q40: 第六孔 | R40: 四合攻a类 | S40: 攻击 | V40: 第六孔 | W40: 四合攻a类 | X40: 攻击 | AE40: 第六孔 | AF40: 四合速深渊领主 | AG40: 攻击 | AJ40: 法力资质 | AK40: 57898.5
B41: 第七孔 | C41: 四合速恶魔武士 | D41: 攻击（完美启） | G41: 第七孔 | H41: 四合速a类 | I41: 攻击 | L41: 第七孔 | M41: 四合速恶魔武士 | N41: 攻击 | Q41: 第七孔 | R41: 四合攻a类 | S41: 攻击 | V41: 第七孔 | W41: 四合攻a类 | X41: 攻击 | AE41: 第七孔 | AF41: 四合速深渊领主 | AG41: 攻击 | AJ41: 防御资质 | AK41: 14773
...

Sheet 综合计算器
F1: 资质宝石 | H1: 家族资 | I1: 合成过程宝石 | J1: 提资宝石 | K1: 数量（孔数加披风） | L1: 资质信息
A2: 选择资质宝石 | C2: 资质信息 | F2: 四合a类 | G2: 生命资质 | J2: 437 | K2: 0 | L2: =INT(SUMPRODUCT((宠物资质信息!$C$2:$G$2=G2)*(宠物资质信息!$C$3:$G$11)*(宠物资质信息!$B$3:$B$11=$F$2))*1.1/2)+INT(J2*K2/2)+IF(H2="有",1832,61) -> 2077 | R2: =H37 -> 自定义1 | S2: =I37 -> 自定义2 | T2: =J37 -> 自定义3 | U2: =K37 -> 自定义4 | V2: =L37 -> 自定义5 | W2: 四合a类 | X2: 四合b类 | Y2: ss圣宠 | Z2: 珍奇宠物 | AA2: 八四光年 | AB2: 熊猫武圣 | AC2: 合计资质
A3: 第一孔 | B3: 自定义5 | C3: 生命资质 | D3: =AC3 -> 180216 | G3: 攻击资质 | H3: 有 | J3: 652 | K3: 11 | L3: =INT(SUMPRODUCT((宠物资质信息!$C$2:$G$2=G3)*(宠物资质信息!$C$3:$G$11)*(宠物资质信息!$B$3:$B$11=$F$2))*1.1/2)+INT(J3*K3/2)+IF(H3="有",1834,611)+IF(I3="有",INT(J3*32*0.02),0) -> 7237 | Q3: 生命资质 | R3: =H38 -> 17144.5 | S3: =I38 -> 18055 | T3: =J38 -> 15938.6 | U3: =K38 -> 32855.15 | V3: =L38 -> 180216 | W3: =L2 -> 2077 | X3: =L8 -> 2153 | Y3: =L14 -> 2991 | Z3: =L20 -> 1573 | AA3: =L26 -> 1444 | AB3: =L32 -> 2010 | AC3: =SUMPRODUCT((R3:AB3)*($R$8:$AB$8)) -> 180216
A4: 第二孔 | B4: 无 | C4: 攻击资质 | D4: =AC4 -> 285372 | G4: 速度资质 | H4: 有 | I4: 有 | J4: 583 | K4: 0 | L4: =INT(SUMPRODUCT((宠物资质信息!$C$2:$G$2=G4)*(宠物资质信息!$C$3:$G$11)*(宠物资质信息!$B$3:$B$11=$F$2))*1.1/2)+INT(J4*K4/2)+IF(H4="有",13740,4580)+IF(I4="有",INT(J4*32*0.02*7.5),0) -> 18691 | Q4: 攻击资质 | R4: =H39 -> 20637.833 | S4: =I39 -> 21925.5 | T4: =J39 -> 12034.258 | U4: =K39 -> 25368.35 | V4: =L39 -> 285372 | W4: =L3 -> 7237 | X4: =L9 -> 7009 | Y4: =L15 -> 3708 | Z4: =L21 -> 8242 | AA4: =L27 -> 5969 | AB4: =L33 -> 2186 | AC4: =SUMPRODUCT((R4:AB4)*($R$8:$AB$8)) -> 285372
A5: 第三孔 | B5: 无 | C5: 速度资质 | D5: =AC5 -> 275000 | G5: 法力资质 | H5: 有 | J5: 430 | K5: 0 | L5: =INT(SUMPRODUCT((宠物资质信息!$C$2:$G$2=G5)*(宠物资质信息!$C$3:$G$11)*(宠物资质信息!$B$3:$B$11=$F$2))*1.1/2)+INT(J5*K5/2)+IF(H5="有",9160,3053)+IF(I5="有",INT(J5*32*0.02*5),0) -> 10832 | Q5: 速度资质 | R5: =H40 -> 67093.167 | S5: =I40 -> 82200 | T5: =J40 -> 24110.517 | U5: =K40 -> 70158.75 | V5: =L40 -> 275000 | W5: =L4 -> 18691 | X5: =L10 -> 18670 | Y5: =L16 -> 19173 | Z5: =L22 -> 7605 | AA5: =L28 -> 1454 | AB5: =L34 -> 2065 | AC5: =SUMPRODUCT((R5:AB5)*($R$8:$AB$8)) -> 275000
A6: 第四孔 | B6: 无 | C6: 法力资质 | D6: =AC6 -> 120000 | G6: 防御资质 | H6: 有 | J6: 436 | K6: 0 | L6: =INT(SUMPRODUCT((宠物资质信息!$C$2:$G$2=G6)*(宠物资质信息!$C$3:$G$11)*(宠物资质信息!$B$3:$B$11=$F$2))*1.1/2)+INT(J6*K6/2)+IF(H6="有",1834,611)+IF(I6="有",INT(J6*32*0.02),0) -> 2686 | Q6: 法力资质 | R6: =H41 -> 44841.833 | S6: =I41 -> 51691.5 | T6: =J41 -> 14171.158 | U6: =K41 -> 41683 | V6: =L41 -> 120000 | W6: =L5 -> 10832 | X6: =L11 -> 11004 | Y6: =L17 -> 10687 | Z6: =L23 -> 4939 | AA6: =L29 -> 1412 | AB6: =L35 -> 740 | AC6: =SUMPRODUCT((R6:AB6)*($R$8:$AB$8)) -> 120000
A7: 第五孔 | B7: 无 | C7: 防御资质 | D7: =AC7 -> 188119 | F7: 资质宝石 | H7: 家族资 | I7: 合成过程宝石 | J7: 提资宝石 | K7: 数量（孔数加披风） | L7: 资质信息 | Q7: 防御资质 | R7: =H42 -> 19250 | S7: =I42 -> 18833.5 | T7: =J42 -> 16054.075 | U7: =K42 -> 33255.5 | V7: =L42 -> 188119 | W7: =L6 -> 2686 | X7: =L12 -> 2686 | Y7: =L18 -> 3776 | Z7: =L24 -> 1554 | AA7: =L30 -> 743 | AB7: =L36 -> 1637 | AC7: =SUMPRODUCT((R7:AB7)*($R$8:$AB$8)) -> 188119
A8: 第六孔 | B8: 无 | C8: 所有带填充色的单元格均可自由修改（合理的） | F8: 四合b类 | G8: 生命资质 | J8: 437 | K8: 0 | L8: =INT(SUMPRODUCT((宠物资质信息!$C$2:$G$2=G8)*(宠物资质信息!$C$3:$G$11)*(宠物资质信息!$B$3:$B$11=$F$8))*1.1/2)+INT(J8*K8/2)+IF(H8="有",1832,61) -> 2153 | Q8: 计数 | R8: =COUNTIF($B$3:$B$12,R$2) -> 0 | S8: =COUNTIF($B$3:$B$12,S$2) -> 0 | T8: =COUNTIF($B$3:$B$12,T$2) -> 0 | U8: =COUNTIF($B$3:$B$12,U$2) -> 0 | V8: =COUNTIF($B$3:$B$12,V$2) -> 1 | W8: =COUNTIF($B$3:$B$12,W$2) -> 0 | X8: =COUNTIF($B$3:$B$12,X$2) -> 0 | Y8: =COUNTIF($B$3:$B$12,Y$2) -> 0 | ... AB8: =COUNTIF($B$3:$B$12,AB$2) -> 0
A9: 第七孔 | B9: 无 | G9: 攻击资质 | H9: 有 | J9: 652 | K9: 11 | L9: =INT(SUMPRODUCT((宠物资质信息!$C$2:$G$2=G9)*(宠物资质信息!$C$3:$G$11)*(宠物资质信息!$B$3:$B$11=$F$8))*1.1/2)+INT(J9*K9/2)+IF(H9="有",1834,611)+IF(I9="有",INT(J9*32*0.02),0) -> 7009 | R9: 宠物资质 | S9: 红色资质 | T9: 资质倍率 | U9: 系数 | V9: 属性点 | W9: 法宝增幅 | X9: 天赋 | Y9: 技能 | Z9: 贴纸 | AA9: 倍率后资质 | AB9: 倍率前资质 | AC9: 属性
A10: 第八孔 | B10: 无 | G10: 速度资质 | H10: 有 | I10: 有 | J10: 583 | K10: 0 | L10: =INT(SUMPRODUCT((宠物资质信息!$C$2:$G$2=G10)*(宠物资质信息!$C$3:$G$11)*(宠物资质信息!$B$3:$B$11=$F$8))*1.1/2)+INT(J10*K10/2)+IF(H10="有",13740,4580)+IF(I10="有",INT(J10*32*0.02*7.5),0) -> 18670 | Q10: 生命 | R10: =D16 -> 4375 | S10: =D3 -> 180216 | T10: =IF($D$37="通常",1,IF($D$37="北极宠",3.2,1.5)) -> 1 | U10: 27.77 | V10: =VLOOKUP(Q10,$Q$39:$U$43,5) -> #N/A | W10: =COUNTIF($D$25,Q10)*0.1 -> 0 | X10: 0.1 | Y10: =SUMPRODUCT(($R$16:$V$16=D21)*($R$17:$V$20)*($Q$17:$Q$20=Q10)) -> 0 | Z10: =X22 -> 0 | AA10: =R10*1.1*T10+S10*1.2*T10 -> 221071.7 | AB10: =S10+R10 -> 184591 | AC10: =INT(AA10/U10*V10*(1+W10+X10+Y10+Z10)) -> #N/A
A11: 第九孔 | B11: 无 | G11: 法力资质 | H11: 有 | J11: 430 | K11: 0 | L11: =INT(SUMPRODUCT((宠物资质信息!$C$2:$G$2=G11)*(宠物资质信息!$C$3:$G$11)*(宠物资质信息!$B$3:$B$11=$F$8))*1.1/2)+INT(J11*K11/2)+IF(H11="有",9160,3053)+IF(I11="有",INT(J11*32*0.02*5),0) -> 11004 | Q11: 攻击 | R11: =D17 -> 12000 | S11: =D4 -> 285372 | T11: =IF($D$37="通常",1,IF($D$37="北极宠",3.2,1.5)) -> 1 | U11: 277.77 | V11: =VLOOKUP(Q11,$Q$39:$U$43,5) -> #N/A | W11: =COUNTIF($D$25,Q11)*0.1 -> 0 | X11: 0.1 | Y11: =SUMPRODUCT(($R$16:$V$16=D22)*($R$17:$V$20)*($Q$17:$Q$20=Q11)) -> 0 | Z11: =X23 -> 0 | AA11: =R11*1.1*T11+S11*1.2*T11 -> 355646.4 | AB11: =S11+R11 -> 297372 | AC11: =INT(AA11/U11*V11*(1+W11+X11+Y11+Z11)) -> #N/A
A12: 第十孔 | B12: 无 | G12: 防御资质 | H12: 有 | J12: 436 | K12: 0 | L12: =INT(SUMPRODUCT((宠物资质信息!$C$2:$G$2=G12)*(宠物资质信息!$C$3:$G$11)*(宠物资质信息!$B$3:$B$11=$F$8))*1.1/2)+INT(J12*K12/2)+IF(H12="有",1834,611)+IF(I12="有",INT(J12*32*0.02),0) -> 2686 | Q12: 速度 | R12: =D18 -> 5250 | S12: =D5 -> 275000 | T12: =IF($D$37="通常",1,IF($D$37="北极宠",3.2,1.5)) -> 1 | U12: 2081.51 | V12: =VLOOKUP(Q12,$Q$39:$U$43,5) -> #N/A | W12: =COUNTIF($D$25,Q12)*0.1 -> 0.1 | X12: 0 | Y12: =SUMPRODUCT(($R$16:$V$16=D23)*($R$17:$V$20)*($Q$17:$Q$20=Q12)) -> 0.4 | Z12: =X24 -> 0.62 | AA12: =R12*1.1*T12+S12*1.2*T12 -> 335775 | AB12: =S12+R12 -> 280250 | AC12: =INT(AA12/U12*V12*(1+W12+X12+Y12+Z12)) -> #N/A
A13: 宠物信息 | B13: 等级 | D13: 100 | F13: 资质宝石 | G13: 机械兽神 | H13: 家族资 | I13: 合成过程宝石 | J13: 提资宝石 | K13: 数量（孔数加披风） | L13: 资质信息 | Q13: 法力 | R13: =D19 -> 5236 | S13: =D6 -> 120000 | T13: =IF($D$37="通常",1,IF($D$37="北极宠",3.2,1.5)) -> 1 | U13: 1388.73 | V13: =VLOOKUP(Q13,$Q$39:$U$43,5) -> #N/A | W13: =COUNTIF($D$25,Q13)*0.1 -> 0 | X13: 0.1 | Y13: =SUMPRODUCT(($R$16:$V$16=D24)*($R$17:$V$20)*($Q$17:$Q$20=Q13)) -> 0.6 | Z13: =X25 -> 0.46 | AA13: =R13*1.1*T13+S13*1.2*T13 -> 149759.6 | AB13: =S13+R13 -> 125236 | AC13: =INT(AA13/U13*V13*(1+W13+X13+Y13+Z13)) -> #N/A
B14: 转生等级 | D14: 2 | F14: ss圣宠 | G14: 生命资质 | J14: 437 | K14: 6 | L14: =INT(SUMPRODUCT((宠物资质信息!$C$2:$G$2=G14)*(宠物资质信息!$C$3:$G$11)*(宠物资质信息!$B$3:$B$11=$G$13))*1.1/2)+INT(J14*K14/2)+IF(H14="有",1832,61) -> 2991 | Q14: 防御 | R14: =D20 -> 1747 | S14: =D7 -> 188119 | T14: =IF($D$37="通常",1,IF($D$37="北极宠",3.2,1.5)) -> 1 | U14: 277.77 | V14: =VLOOKUP(Q14,$Q$39:$U$43,5) -> #N/A | W14: =COUNTIF($D$25,Q14)*0.1 -> 0 | X14: 0.3 | Y14: 0 | Z14: =X26 -> 0 | AA14: =R14*1.1*T14+S14*1.2*T14 -> 227664.5 | AB14: =S14+R14 -> 189866 | AC14: =INT(AA14/U14*V14*(1+W14+X14+Y14+Z14))+INT(AB14*T27*(1+X14+W14+Y14+Z14)) -> #N/A
B15: 进化等级 | D15: 100 | G15: 攻击资质 | H15: 有 | J15: 652 | K15: 0 | L15: =INT(SUMPRODUCT((宠物资质信息!$C$2:$G$2=G15)*(宠物资质信息!$C$3:$G$11)*(宠物资质信息!$B$3:$B$11=$G$13))*1.1/2)+INT(J15*K15/2)+IF(H15="有",1834,611)+IF(I15="有",INT(J15*32*0.02),0) -> 3708
B16: 基础资质 | C16: 生命资质 | D16: 4375 | G16: 速度资质 | H16: 有 | I16: 有 | J16: 583 | K16: 0 | L16: =INT(SUMPRODUCT((宠物资质信息!$C$2:$G$2=G16)*(宠物资质信息!$C$3:$G$11)*(宠物资质信息!$B$3:$B$11=$G$13))*1.1/2)+INT(J16*K16/2)+IF(H16="有",13740,4580)+IF(I16="有",INT(J16*32*0.02*7.5),0) -> 19173 | Q16: 技能 | R16: b级 | S16: a级 | T16: 神级 | U16: 魂级 | V16: 圣技 | AA16: =AA10/1.2 -> 184226.42
C17: 攻击资质 | D17: 12000 | G17: 法力资质 | H17: 有 | J17: 430 | K17: 0 | L17: =INT(SUMPRODUCT((宠物资质信息!$C$2:$G$2=G17)*(宠物资质信息!$C$3:$G$11)*(宠物资质信息!$B$3:$B$11=$G$13))*1.1/2)+INT(J17*K17/2)+IF(H17="有",9160,3053)+IF(I17="有",INT(J17*32*0.02*5),0) -> 10687 | Q17: 生命 | R17: 0.15 | S17: 0.25 | T17: 0.3 | V17: 0.8 | AA17: =AA11/1.2 -> 296372
C18: 速度资质 | D18: 5250 | G18: 防御资质 | H18: 有 | J18: 436 | K18: 5 | L18: =INT(SUMPRODUCT((宠物资质信息!$C$2:$G$2=G18)*(宠物资质信息!$C$3:$G$11)*(宠物资质信息!$B$3:$B$11=$G$13))*1.1/2)+INT(J18*K18/2)+IF(H18="有",1834,611)+IF(I18="有",INT(J18*32*0.02),0) -> 3776 | Q18: 攻击 | R18: 0.15 | S18: 0.25 | T18: 0.3 | V18: 0.6 | AA18: =AA12/1.2 -> 279812.5
C19: 法力资质 | D19: 5236 | F19: 资质宝石 | G19: 白色幻影 | H19: 家族资 | I19: 合成过程宝石 | J19: 提资宝石 | K19: 数量（孔数加披风） | L19: 资质信息 | Q19: 速度 | R19: 0.1 | S19: 0.15 | T19: 0.2 | V19: 0.4 | AA19: =AA13/1.2 -> 124799.67
C20: 防御资质 | D20: 1747 | F20: 珍奇宠物 | G20: 生命资质 | J20: 437 | K20: 0 | L20: =INT(SUMPRODUCT((宠物资质信息!$C$2:$G$2=G20)*(宠物资质信息!$C$3:$G$11)*(宠物资质信息!$B$3:$B$11=$G$19))*1.1/2)+INT(J20*K20/2)+IF(H20="有",1832,61) -> 1573 | Q20: 法力 | R20: 0.15 | S20: 0.25 | T20: 0.3 | V20: 0.6 | AA20: =AA14/1.2 -> 189720.42
B21: 技能 | C21: 生命 | D21: 无 | G21: 攻击资质 | H21: 有 | I21: 有 | J21: 652 | K21: 12 | L21: =INT(SUMPRODUCT((宠物资质信息!$C$2:$G$2=G21)*(宠物资质信息!$C$3:$G$11)*(宠物资质信息!$B$3:$B$11=$G$19))*1.1/2)+INT(J21*K21/2)+IF(H21="有",1834,611)+IF(I21="有",INT(J21*32*0.02),0) -> 8242 | Q21: 贴纸 | R21: 1 | S21: 2 | T21: 3 | U21: 4 | V21: 5 | W21: 贴纸数量 | X21: 增幅
C22: 攻击 | D22: 无 | G22: 速度资质 | H22: 无 | J22: 583 | K22: 0 | L22: =INT(SUMPRODUCT((宠物资质信息!$C$2:$G$2=G22)*(宠物资质信息!$C$3:$G$11)*(宠物资质信息!$B$3:$B$11=$G$19))*1.1/2)+INT(J22*K22/2)+IF(H22="有",13740,4580)+IF(I22="有",INT(J22*32*0.02*7.5),0) -> 7605 | Q22: 生命贴 | R22: 0.26 | S22: 0.16 | T22: 0.16 | U22: 0.16 | V22: 0.12 | W22: =COUNTIF($D$26:$D$30,Q22) -> 0 | X22: =SUMPRODUCT(($R$21:$V$21<=W22)*(R22:V22)) -> 0
C23: 速度 | D23: 圣技 | G23: 法力资质 | H23: 无 | J23: 430 | K23: 0 | L23: =INT(SUMPRODUCT((宠物资质信息!$C$2:$G$2=G23)*(宠物资质信息!$C$3:$G$11)*(宠物资质信息!$B$3:$B$11=$G$19))*1.1/2)+INT(J23*K23/2)+IF(H23="有",9160,3053)+IF(I23="有",INT(J23*32*0.02*5),0) -> 4939 | Q23: 攻击贴 | R23: 0.26 | S23: 0.2 | T23: 0.16 | U23: 0.16 | V23: 0.16 | W23: =COUNTIF($D$26:$D$30,Q23) -> 0 | X23: =SUMPRODUCT(($R$21:$V$21<=W23)*(R23:V23)) -> 0
C24: 法力 | D24: 圣技 | G24: 防御资质 | H24: 无 | J24: 436 | K24: 0 | L24: =INT(SUMPRODUCT((宠物资质信息!$C$2:$G$2=G24)*(宠物资质信息!$C$3:$G$11)*(宠物资质信息!$B$3:$B$11=$G$19))*1.1/2)+INT(J24*K24/2)+IF(H24="有",1834,611)+IF(I24="有",INT(J24*32*0.02),0) -> 1554 | Q24: 速度贴 | R24: 0.26 | S24: 0.2 | T24: 0.16 | U24: 0.16 | V24: 0.16 | W24: =COUNTIF($D$26:$D$30,Q24) -> 3 | X24: =SUMPRODUCT(($R$21:$V$21<=W24)*(R24:V24))+IF(W25>2,0.06,0) -> 0.62
B25: 宠物法宝 | D25: 速度 | F25: 资质宝石 | H25: 家族资 | I25: 合成过程宝石 | J25: 提资宝石 | K25: 数量（孔数加披风） | L25: 资质信息 | Q25: 法力贴 | R25: 0.26 | S25: 0.2 | T25: 0.16 | U25: 0.16 | V25: 0.16 | W25: =COUNTIF($D$26:$D$30,Q25) -> 2 | X25: =SUMPRODUCT(($R$21:$V$21<=W25)*(R25:V25)) -> 0.46
B26: 贴纸 | C26: 第一贴 | D26: 速度贴 | F26: 八四光年 | G26: 生命资质 | J26: 437 | K26: 0 | L26: =INT(SUMPRODUCT((宠物资质信息!$C$2:$G$2=G26)*(宠物资质信息!$C$3:$G$13)*(宠物资质信息!$B$3:$B$13=$F$26))*1.1/2)+INT(J26*K26/2) -> 1444 | Q26: 防御贴 | R26: 0.36 | S26: 0.26 | T26: 0.22 | U26: 0.16 | V26: 0.12 | W26: =COUNTIF($D$26:$D$30,Q26) -> 0 | X26: =SUMPRODUCT(($R$21:$V$21<=W26)*(R26:V26))+IF(W22>1,0.08,0) -> 0
C27: 第二贴 | D27: 速度贴 | G27: 攻击资质 | J27: 652 | K27: 11 | L27: =INT(SUMPRODUCT((宠物资质信息!$C$2:$G$2=G27)*(宠物资质信息!$C$3:$G$13)*(宠物资质信息!$B$3:$B$13=$F$26))*1.1/2)+INT(J27*K27/2) -> 5969 | Q27: 里世界系数 | R27: =D31 -> 11648 | S27: =0.18/10000 -> 1.8e-05 | T27: =R27*S27 -> 0.209664
C28: 第三贴 | D28: 速度贴 | G28: 速度资质 | J28: 583 | K28: 0 | L28: =INT(SUMPRODUCT((宠物资质信息!$C$2:$G$2=G28)*(宠物资质信息!$C$3:$G$13)*(宠物资质信息!$B$3:$B$13=$F$26))*1.1/2)+INT(J28*K28/2) -> 1454 | Q28: 属性点 | R28: 基础属性点 | S28: 进化属性点 | T28: 自由属性点 | U28: =(IF(D14=2,(198+70+INT(D13/5)*2),IF(D14=1,(198+10+INT(D13/5)*2),(D13-1)*2))+D15)*IF(E37="北极宠bug",2,1) -> 408 | W28: =SUM(V10:V14) -> #N/A
C29: 第四贴 | D29: 法力贴 | G29: 法力资质 | J29: 430 | K29: 0 | L29: =INT(SUMPRODUCT((宠物资质信息!$C$2:$G$2=G29)*(宠物资质信息!$C$3:$G$13)*(宠物资质信息!$B$3:$B$13=$F$26))*1.1/2)+INT(J29*K29/2) -> 1412 | Q29: 生命 | R29: =$D$13-1 -> 99 | S29: =$D$15*3/4 -> 75 | T29: =R29+S29 -> 174 | U29: =R29+S29+$U$28 -> 582 | W29: =SUM(T29:T33)+U28 -> 1203
C30: 第五贴 | D30: 法力贴 | G30: 防御资质 | J30: 436 | K30: 0 | L30: =INT(SUMPRODUCT((宠物资质信息!$C$2:$G$2=G30)*(宠物资质信息!$C$3:$G$13)*(宠物资质信息!$B$3:$B$13=$F$26))*1.1/2)+INT(J30*K30/2) -> 743 | Q30: 攻击 | R30: =$D$13-1 -> 99 | S30: =$D$15*3/4 -> 75 | T30: =R30+S30 -> 174 | U30: =R30+S30+$U$28 -> 582 | W30: =W29-W28 -> #N/A
B31: 里世界潜力 | D31: 11648 | F31: 资质宝石 | H31: 家族资 | I31: 合成过程宝石 | J31: 提资宝石 | K31: 数量（孔数加披风） | L31: 资质信息 | Q31: 速度 | R31: =$D$13-1 -> 99 | S31: =$D$15*3/4 -> 75 | T31: =R31+S31 -> 174 | U31: =R31+S31+$U$28 -> 582
B32: 属性点数分配侧重 | C32: 第一属性 | D32: 速度 | E32: =U39 -> 293 | F32: 熊猫武圣 | G32: 生命资质 | J32: 437 | K32: 0 | L32: =INT(SUMPRODUCT((宠物资质信息!$C$2:$G$2=G32)*(宠物资质信息!$C$3:$G$13)*(宠物资质信息!$B$3:$B$13=$F$32))*1.1/2)+INT(J32*K32/2) -> 2010 | Q32: 法力 | R32: =$D$13-1 -> 99 | S32: =$D$15*3/4 -> 75 | T32: =R32+S32 -> 174 | U32: =R32+S32+$U$28 -> 582
C33: 第二属性 | D33: 法力 | E33: =U40 -> #N/A | G33: 攻击资质 | J33: 652 | K33: 1 | L33: =INT(SUMPRODUCT((宠物资质信息!$C$2:$G$2=G33)*(宠物资质信息!$C$3:$G$13)*(宠物资质信息!$B$3:$B$13=$F$32))*1.1/2)+INT(J33*K33/2) -> 2186 | Q33: 防御 | R33: =$D$13-1 -> 99 | S33: 0 | T33: =R33+S33 -> 99 | U33: =R33+S33+$U$28 -> 507
C34: 第三属性 | D34: 攻击 | E34: =U41 -> #N/A | G34: 速度资质 | J34: 583 | K34: 3 | L34: =INT(SUMPRODUCT((宠物资质信息!$C$2:$G$2=G34)*(宠物资质信息!$C$3:$G$13)*(宠物资质信息!$B$3:$B$13=$F$32))*1.1/2)+INT(J34*K34/2) -> 2065 | Q34: 生命 | R34: =D43 -> 5000000 | S34: =W10+X10+Y10+Z10+1 -> 1.1 | T34: =AA10 -> 221071.7 | U34: =AB10 -> 184591 | V34: =U10 -> 27.77 | W34: =ROUNDUP((R34/S34*V34/T34),0) -> 571
C35: 第四属性 | D35: 生命 | E35: =U42 -> #N/A | G35: 法力资质 | J35: 430 | K35: 0 | L35: =INT(SUMPRODUCT((宠物资质信息!$C$2:$G$2=G35)*(宠物资质信息!$C$3:$G$13)*(宠物资质信息!$B$3:$B$13=$F$32))*1.1/2)+INT(J35*K35/2) -> 740 | Q35: 攻击 | R35: =D44 -> 500000 | S35: =W11+X11+Y11+Z11+1 -> 1.1 | T35: =AA11 -> 355646.4 | U35: =AB11 -> 297372 | V35: =U11 -> 277.77 | W35: =ROUNDUP((R35/S35*V35/T35),0) -> 356
C36: 第五属性 | D36: 防御 | E36: =U43 -> #N/A | G36: 防御资质 | J36: 436 | K36: 0 | L36: =INT(SUMPRODUCT((宠物资质信息!$C$2:$G$2=G36)*(宠物资质信息!$C$3:$G$13)*(宠物资质信息!$B$3:$B$13=$F$32))*1.1/2)+INT(J36*K36/2) -> 1637 | Q36: 速度 | R36: =D45 -> 100000 | S36: =W12+X12+Y12+Z12+1 -> 2.12 | T36: =AA12 -> 335775 | U36: =AB12 -> 280250 | V36: =U12 -> 2081.51 | W36: =ROUNDUP((R36/S36*V36/T36),0) -> 293
